Workbook

Sheet TdB
B1: Mois | C1: =EOMONTH(E1,-2)+1 -> 46174 | E1: =EOMONTH(G1,-2)+1 -> 46204 | G1: =DATE(YEAR(TODAY()),Month(TODAY()),1) -> 46235 | I1: =EOMONTH(G1,0)+1 -> 46266 | K1: =EOMONTH(I1,0)+1 -> 46296 | M1: =EOMONTH(K1,0)+1 -> 46327 | O1: =EOMONTH(M1,0)+1 -> 46357 | Q1: =EOMONTH(O1,0)+1 -> 46388 | S1: =EOMONTH(Q1,0)+1 -> 46419 | U1: =EOMONTH(S1,0)+1 -> 46447 | W1: =EOMONTH(U1,0)+1 -> 46478 | Y1: =EOMONTH(W1,0)+1 -> 46508 | AA1: =EOMONTH(Y1,0)+1 -> 46539 | AC1: =EOMONTH(AA1,0)+1 -> 46569 | AE1: =EOMONTH(AC1,0)+1 -> 46600 | AG1: =EOMONTH(AE1,0)+1 -> 46631
A2: Total | B2: CA nuitée | C2: =SUMIFS(dataMail!$R:$R,dataMail!$C:$C,"<>Annulation",dataMail!$G:$G,"<"&E$1,dataMail!$G:$G,">="&C$1) -> 38109.178 | E2: =SUMIFS(dataMail!$R:$R,dataMail!$C:$C,"<>Annulation",dataMail!$G:$G,"<"&G$1,dataMail!$G:$G,">="&E$1) -> 29567.798 | G2: =SUMIFS(dataMail!$R:$R,dataMail!$C:$C,"<>Annulation",dataMail!$G:$G,"<"&I$1,dataMail!$G:$G,">="&G$1) -> 30273.667 | I2: =SUMIFS(dataMail!$R:$R,dataMail!$C:$C,"<>Annulation",dataMail!$G:$G,"<"&K$1,dataMail!$G:$G,">="&I$1) -> 32476.561 | K2: =SUMIFS(dataMail!$R:$R,dataMail!$C:$C,"<>Annulation",dataMail!$G:$G,"<"&M$1,dataMail!$G:$G,">="&K$1) -> 45567.947 | M2: =SUMIFS(dataMail!$R:$R,dataMail!$C:$C,"<>Annulation",dataMail!$G:$G,"<"&O$1,dataMail!$G:$G,">="&M$1) -> 29328.625 | O2: =SUMIFS(dataMail!$R:$R,dataMail!$C:$C,"<>Annulation",dataMail!$G:$G,"<"&Q$1,dataMail!$G:$G,">="&O$1) -> 21874.036 | Q2: =SUMIFS(dataMail!$R:$R,dataMail!$C:$C,"<>Annulation",dataMail!$G:$G,"<"&S$1,dataMail!$G:$G,">="&Q$1) -> 15940.112 | S2: =SUMIFS(dataMail!$R:$R,dataMail!$C:$C,"<>Annulation",dataMail!$G:$G,"<"&U$1,dataMail!$G:$G,">="&S$1) -> 11937.696 | U2: =SUMIFS(dataMail!$R:$R,dataMail!$C:$C,"<>Annulation",dataMail!$G:$G,"<"&W$1,dataMail!$G:$G,">="&U$1) -> 4395.712 | W2: =SUMIFS(dataMail!$R:$R,dataMail!$C:$C,"<>Annulation",dataMail!$G:$G,"<"&Y$1,dataMail!$G:$G,">="&W$1) -> 5596.9216 | Y2: =SUMIFS(dataMail!$R:$R,dataMail!$C:$C,"<>Annulation",dataMail!$G:$G,"<"&AC$1,dataMail!$G:$G,">="&Y$1) -> 11413.76 | AA2: =SUMIFS(dataMail!$R:$R,dataMail!$C:$C,"<>Annulation",dataMail!$G:$G,"<"&AC$1,dataMail!$G:$G,">="&AA$1) -> 1656.832 | AC2: =SUMIFS(dataMail!$R:$R,dataMail!$C:$C,"<>Annulation",dataMail!$G:$G,"<"&AE$1,dataMail!$G:$G,">="&AC$1) -> 1080.24 | AE2: =SUMIFS(dataMail!$R:$R,dataMail!$C:$C,"<>Annulation",dataMail!$G:$G,"<"&AI$1,dataMail!$G:$G,">="&AE$1) -> 0 | AG2: =SUMIFS(dataMail!$R:$R,dataMail!$C:$C,"<>Annulation",dataMail!$G:$G,"<"&AK$1,dataMail!$G:$G,">="&AG$1) -> 0
B3: nb Nuitée | C3: =IFERROR(SUMIFS(dataMail!$I:$I,dataMail!$C:$C,"<>Annulation",dataMail!$G:$G,"<"&E$1,dataMail!$G:$G,">="&C$1),"-") -> 281 | E3: =IFERROR(SUMIFS(dataMail!$I:$I,dataMail!$C:$C,"<>Annulation",dataMail!$G:$G,"<"&G$1,dataMail!$G:$G,">="&E$1),"-") -> 241 | G3: =IFERROR(SUMIFS(dataMail!$I:$I,dataMail!$C:$C,"<>Annulation",dataMail!$G:$G,"<"&I$1,dataMail!$G:$G,">="&G$1),"-") -> 280 | I3: =IFERROR(SUMIFS(dataMail!$I:$I,dataMail!$C:$C,"<>Annulation",dataMail!$G:$G,"<"&K$1,dataMail!$G:$G,">="&I$1),"-") -> 248 | K3: =IFERROR(SUMIFS(dataMail!$I:$I,dataMail!$C:$C,"<>Annulation",dataMail!$G:$G,"<"&M$1,dataMail!$G:$G,">="&K$1),"-") -> 275 | M3: =IFERROR(SUMIFS(dataMail!$I:$I,dataMail!$C:$C,"<>Annulation",dataMail!$G:$G,"<"&O$1,dataMail!$G:$G,">="&M$1),"-") -> 184 | O3: =IFERROR(SUMIFS(dataMail!$I:$I,dataMail!$C:$C,"<>Annulation",dataMail!$G:$G,"<"&Q$1,dataMail!$G:$G,">="&O$1),"-") -> 127 | Q3: =IFERROR(SUMIFS(dataMail!$I:$I,dataMail!$C:$C,"<>Annulation",dataMail!$G:$G,"<"&S$1,dataMail!$G:$G,">="&Q$1),"-") -> 75 | S3: =IFERROR(SUMIFS(dataMail!$I:$I,dataMail!$C:$C,"<>Annulation",dataMail!$G:$G,"<"&U$1,dataMail!$G:$G,">="&S$1),"-") -> 65 | U3: =IFERROR(SUMIFS(dataMail!$I:$I,dataMail!$C:$C,"<>Annulation",dataMail!$G:$G,"<"&W$1,dataMail!$G:$G,">="&U$1),"-") -> 36 | W3: =IFERROR(SUMIFS(dataMail!$I:$I,dataMail!$C:$C,"<>Annulation",dataMail!$G:$G,"<"&Y$1,dataMail!$G:$G,">="&W$1),"-") -> 35 | Y3: =IFERROR(SUMIFS(dataMail!$I:$I,dataMail!$C:$C,"<>Annulation",dataMail!$G:$G,"<"&AC$1,dataMail!$G:$G,">="&Y$1),"-") -> 68 | AA3: =IFERROR(SUMIFS(dataMail!$I:$I,dataMail!$C:$C,"<>Annulation",dataMail!$G:$G,"<"&AC$1,dataMail!$G:$G,">="&AA$1),"-") -> 19 | AC3: =IFERROR(SUMIFS(dataMail!$I:$I,dataMail!$C:$C,"<>Annulation",dataMail!$G:$G,"<"&AE$1,dataMail!$G:$G,">="&AC$1),"-") -> 13 | AE3: =IFERROR(SUMIFS(dataMail!$I:$I,dataMail!$C:$C,"<>Annulation",dataMail!$G:$G,"<"&AI$1,dataMail!$G:$G,">="&AE$1),"-") -> 0 | AG3: =IFERROR(SUMIFS(dataMail!$I:$I,dataMail!$C:$C,"<>Annulation",dataMail!$G:$G,"<"&AK$1,dataMail!$G:$G,">="&AG$1),"-") -> 0
B4: Taux Yield | C4: =C3/(12*DAY(EOMONTH(C1,0))) -> 0.78055556 | E4: =E3/(12*DAY(EOMONTH(E1,0))) -> 0.64784946 | G4: =G3/(12*DAY(EOMONTH(G1,0))) -> 0.75268817 | I4: =I3/(12*DAY(EOMONTH(I1,0))) -> 0.68888889 | K4: =K3/(12*DAY(EOMONTH(K1,0))) -> 0.73924731 | M4: =M3/(12*DAY(EOMONTH(M1,0))) -> 0.51111111 | O4: =O3/(12*DAY(EOMONTH(O1,0))) -> 0.34139785 | Q4: =Q3/(12*DAY(EOMONTH(Q1,0))) -> 0.2016129 | S4: =S3/(12*DAY(EOMONTH(S1,0))) -> 0.19345238 | U4: =U3/(12*DAY(EOMONTH(U1,0))) -> 0.096774194 | W4: =W3/(12*DAY(EOMONTH(W1,0))) -> 0.097222222 | Y4: =Y3/(12*DAY(EOMONTH(Y1,0))) -> 0.1827957 | AA4: =AA3/(12*DAY(EOMONTH(AA1,0))) -> 0.052777778 | AC4: =AC3/(12*DAY(EOMONTH(AC1,0))) -> 0.034946237 | AE4: =AE3/(12*DAY(EOMONTH(AE1,0))) -> 0 | AG4: =AG3/(12*DAY(EOMONTH(AG1,0))) -> 0
B5: Moyenne | C5: =C2/C3 -> 135.61985 | E5: =E2/E3 -> 122.68796 | G5: =G2/G3 -> 108.12024 | I5: =I2/I3 -> 130.95388 | K5: =K2/K3 -> 165.70163 | M5: =M2/M3 -> 159.3947 | O5: =O2/O3 -> 172.2365 | Q5: =Q2/Q3 -> 212.53483 | S5: =S2/S3 -> 183.65686 | U5: =U2/U3 -> 122.10311 | W5: =W2/W3 -> 159.91205 | Y5: =Y2/Y3 -> 167.84941 | AA5: =AA2/AA3 -> 87.201684 | AC5: =AC2/AC3 -> 83.095385 | AE5: =AE2/AE3 -> #DIV/0! | AG5: =AG2/AG3 -> #DIV/0!
B6: Taux Reel | C6: =1-SUM(D11:D41)/(12*DAY(EOMONTH(C3,0))) -> 0.82526882 | E6: =1-SUM(F11:F41)/(12*DAY(EOMONTH(E3,0))) -> 0.78763441 | G6: =1-SUM(H11:H41)/(12*DAY(EOMONTH(G3,0))) -> 0.81989247 | I6: =1-SUM(J11:J41)/(12*DAY(EOMONTH(I3,0))) -> 0.84722222 | K6: =1-SUM(L11:L41)/(12*DAY(EOMONTH(K3,0))) -> 0.87096774 | M6: =1-SUM(N11:N41)/(12*DAY(EOMONTH(M3,0))) -> 0.61827957 | O6: =1-SUM(P11:P41)/(12*DAY(EOMONTH(O3,0))) -> 0.41666667 | Q6: =1-SUM(R11:R41)/(12*DAY(EOMONTH(Q3,0))) -> 0.2983871 | S6: =1-SUM(T11:T41)/(12*DAY(EOMONTH(S3,0))) -> 0.27419355 | U6: =1-SUM(V11:V41)/(12*DAY(EOMONTH(U3,0))) -> 0.074404762 | W6: =1-SUM(X11:X41)/(12*DAY(EOMONTH(W3,0))) -> 0.13988095 | Y6: =1-SUM(Z11:Z41)/(12*DAY(EOMONTH(Y3,0))) -> 0.21505376 | AA6: =1-SUM(AB11:AB41)/(12*DAY(EOMONTH(AA3,0))) -> 0.16397849 | AC6: =1-SUM(AD11:AD41)/(12*DAY(EOMONTH(AC3,0))) -> 0.11827957 | AE6: =1-SUM(AF11:AF41)/(12*DAY(EOMONTH(AE3,0))) -> 0.17473118 | AG6: =1-SUM(AH11:AH41)/(12*DAY(EOMONTH(AG3,0))) -> 0.12903226
B7: CA Sup | C7: =SUMIFS(dataMail!$S:$S,dataMail!$C:$C,"<>Annulation",dataMail!$G:$G,"<"&E$1,dataMail!$G:$G,">="&C$1) -> 36 | E7: =SUMIFS(dataMail!$S:$S,dataMail!$C:$C,"<>Annulation",dataMail!$G:$G,"<"&G$1,dataMail!$G:$G,">="&E$1) -> 558 | G7: =SUMIFS(dataMail!$S:$S,dataMail!$C:$C,"<>Annulation",dataMail!$G:$G,"<"&I$1,dataMail!$G:$G,">="&G$1) -> 0 | I7: =SUMIFS(dataMail!$S:$S,dataMail!$C:$C,"<>Annulation",dataMail!$G:$G,"<"&K$1,dataMail!$G:$G,">="&I$1) -> 720 | K7: =SUMIFS(dataMail!$S:$S,dataMail!$C:$C,"<>Annulation",dataMail!$G:$G,"<"&M$1,dataMail!$G:$G,">="&K$1) -> 630 | M7: =SUMIFS(dataMail!$S:$S,dataMail!$C:$C,"<>Annulation",dataMail!$G:$G,"<"&O$1,dataMail!$G:$G,">="&M$1) -> 396 | O7: =SUMIFS(dataMail!$S:$S,dataMail!$C:$C,"<>Annulation",dataMail!$G:$G,"<"&Q$1,dataMail!$G:$G,">="&O$1) -> 108 | Q7: =SUMIFS(dataMail!$S:$S,dataMail!$C:$C,"<>Annulation",dataMail!$G:$G,"<"&S$1,dataMail!$G:$G,">="&Q$1) -> 36 | S7: =SUMIFS(dataMail!$S:$S,dataMail!$C:$C,"<>Annulation",dataMail!$G:$G,"<"&U$1,dataMail!$G:$G,">="&S$1) -> 72 | U7: =SUMIFS(dataMail!$S:$S,dataMail!$C:$C,"<>Annulation",dataMail!$G:$G,"<"&W$1,dataMail!$G:$G,">="&U$1) -> 216 | W7: =SUMIFS(dataMail!$S:$S,dataMail!$C:$C,"<>Annulation",dataMail!$G:$G,"<"&Y$1,dataMail!$G:$G,">="&W$1) -> 72 | Y7: =SUMIFS(dataMail!$S:$S,dataMail!$C:$C,"<>Annulation",dataMail!$G:$G,"<"&AC$1,dataMail!$G:$G,">="&Y$1) -> 0 | AA7: =SUMIFS(dataMail!$S:$S,dataMail!$C:$C,"<>Annulation",dataMail!$G:$G,"<"&AC$1,dataMail!$G:$G,">="&AA$1) -> 0 | AC7: =SUMIFS(dataMail!$S:$S,dataMail!$C:$C,"<>Annulation",dataMail!$G:$G,"<"&AE$1,dataMail!$G:$G,">="&AC$1) -> 0 | AE7: =SUMIFS(dataMail!$S:$S,dataMail!$C:$C,"<>Annulation",dataMail!$G:$G,"<"&AI$1,dataMail!$G:$G,">="&AE$1) -> 0 | AG7: =SUMIFS(dataMail!$S:$S,dataMail!$C:$C,"<>Annulation",dataMail!$G:$G,"<"&AK$1,dataMail!$G:$G,">="&AG$1) -> 0
A8: HotelBeds | B8: CA Total | C8: =SUMIFS(dataMail!$R:$R,dataMail!$C:$C,"<>Annulation",dataMail!$G:$G,"<"&E$1,dataMail!$G:$G,">="&C$1,dataMail!$D:$D,$A8) +SUMIFS(dataMail!$S:$S,dataMail!$C:$C,"<>Annulation",dataMail!$G:$G,"<"&E$1,dataMail!$G:$G,">="&C$1,dataMail!$D:$D,$A8) -> 0 | E8: =SUMIFS(dataMail!$R:$R,dataMail!$C:$C,"<>Annulation",dataMail!$G:$G,"<"&G$1,dataMail!$G:$G,">="&E$1,dataMail!$D:$D,$A8) +SUMIFS(dataMail!$S:$S,dataMail!$C:$C,"<>Annulation",dataMail!$G:$G,"<"&G$1,dataMail!$G:$G,">="&E$1,dataMail!$D:$D,$A8) -> 0 | G8: =SUMIFS(dataMail!$R:$R,dataMail!$C:$C,"<>Annulation",dataMail!$G:$G,"<"&I$1,dataMail!$G:$G,">="&G$1,dataMail!$D:$D,$A8) +SUMIFS(dataMail!$S:$S,dataMail!$C:$C,"<>Annulation",dataMail!$G:$G,"<"&I$1,dataMail!$G:$G,">="&G$1,dataMail!$D:$D,$A8) -> 0 | I8: =SUMIFS(dataMail!$R:$R,dataMail!$C:$C,"<>Annulation",dataMail!$G:$G,"<"&K$1,dataMail!$G:$G,">="&I$1,dataMail!$D:$D,$A8) +SUMIFS(dataMail!$S:$S,dataMail!$C:$C,"<>Annulation",dataMail!$G:$G,"<"&K$1,dataMail!$G:$G,">="&I$1,dataMail!$D:$D,$A8) -> 287.72 | K8: =SUMIFS(dataMail!$R:$R,dataMail!$C:$C,"<>Annulation",dataMail!$G:$G,"<"&M$1,dataMail!$G:$G,">="&K$1,dataMail!$D:$D,$A8) +SUMIFS(dataMail!$S:$S,dataMail!$C:$C,"<>Annulation",dataMail!$G:$G,"<"&M$1,dataMail!$G:$G,">="&K$1,dataMail!$D:$D,$A8) -> 2253.824 | M8: =SUMIFS(dataMail!$R:$R,dataMail!$C:$C,"<>Annulation",dataMail!$G:$G,"<"&O$1,dataMail!$G:$G,">="&M$1,dataMail!$D:$D,$A8) +SUMIFS(dataMail!$S:$S,dataMail!$C:$C,"<>Annulation",dataMail!$G:$G,"<"&O$1,dataMail!$G:$G,">="&M$1,dataMail!$D:$D,$A8) -> 612.992 | O8: =SUMIFS(dataMail!$R:$R,dataMail!$C:$C,"<>Annulation",dataMail!$G:$G,"<"&Q$1,dataMail!$G:$G,">="&O$1,dataMail!$D:$D,$A8) +SUMIFS(dataMail!$S:$S,dataMail!$C:$C,"<>Annulation",dataMail!$G:$G,"<"&Q$1,dataMail!$G:$G,">="&O$1,dataMail!$D:$D,$A8) -> 0 | Q8: =SUMIFS(dataMail!$R:$R,dataMail!$C:$C,"<>Annulation",dataMail!$G:$G,"<"&S$1,dataMail!$G:$G,">="&Q$1,dataMail!$D:$D,$A8) +SUMIFS(dataMail!$S:$S,dataMail!$C:$C,"<>Annulation",dataMail!$G:$G,"<"&S$1,dataMail!$G:$G,">="&Q$1,dataMail!$D:$D,$A8) -> 0 | S8: =SUMIFS(dataMail!$R:$R,dataMail!$C:$C,"<>Annulation",dataMail!$G:$G,"<"&U$1,dataMail!$G:$G,">="&S$1,dataMail!$D:$D,$A8) +SUMIFS(dataMail!$S:$S,dataMail!$C:$C,"<>Annulation",dataMail!$G:$G,"<"&U$1,dataMail!$G:$G,">="&S$1,dataMail!$D:$D,$A8) -> 0 | U8: =SUMIFS(dataMail!$R:$R,dataMail!$C:$C,"<>Annulation",dataMail!$G:$G,"<"&W$1,dataMail!$G:$G,">="&U$1,dataMail!$D:$D,$A8) +SUMIFS(dataMail!$S:$S,dataMail!$C:$C,"<>Annulation",dataMail!$G:$G,"<"&W$1,dataMail!$G:$G,">="&U$1,dataMail!$D:$D,$A8) -> 0 | W8: =SUMIFS(dataMail!$R:$R,dataMail!$C:$C,"<>Annulation",dataMail!$G:$G,"<"&Y$1,dataMail!$G:$G,">="&W$1,dataMail!$D:$D,$A8) +SUMIFS(dataMail!$S:$S,dataMail!$C:$C,"<>Annulation",dataMail!$G:$G,"<"&Y$1,dataMail!$G:$G,">="&W$1,dataMail!$D:$D,$A8) -> 0 | Y8: =SUMIFS(dataMail!$R:$R,dataMail!$C:$C,"<>Annulation",dataMail!$G:$G,"<"&AC$1,dataMail!$G:$G,">="&Y$1,dataMail!$D:$D,$A8) +SUMIFS(dataMail!$S:$S,dataMail!$C:$C,"<>Annulation",dataMail!$G:$G,"<"&AC$1,dataMail!$G:$G,">="&Y$1,dataMail!$D:$D,$A8) -> 0 | AA8: =SUMIFS(dataMail!$R:$R,dataMail!$C:$C,"<>Annulation",dataMail!$G:$G,"<"&AC$1,dataMail!$G:$G,">="&AA$1,dataMail!$D:$D,$A8) +SUMIFS(dataMail!$S:$S,dataMail!$C:$C,"<>Annulation",dataMail!$G:$G,"<"&AC$1,dataMail!$G:$G,">="&AA$1,dataMail!$D:$D,$A8) -> 0 | AC8: =SUMIFS(dataMail!$R:$R,dataMail!$C:$C,"<>Annulation",dataMail!$G:$G,"<"&AE$1,dataMail!$G:$G,">="&AC$1,dataMail!$D:$D,$A8) +SUMIFS(dataMail!$S:$S,dataMail!$C:$C,"<>Annulation",dataMail!$G:$G,"<"&AE$1,dataMail!$G:$G,">="&AC$1,dataMail!$D:$D,$A8) -> 0 | AE8: =SUMIFS(dataMail!$R:$R,dataMail!$C:$C,"<>Annulation",dataMail!$G:$G,"<"&AI$1,dataMail!$G:$G,">="&AE$1,dataMail!$D:$D,$A8) +SUMIFS(dataMail!$S:$S,dataMail!$C:$C,"<>Annulation",dataMail!$G:$G,"<"&AI$1,dataMail!$G:$G,">="&AE$1,dataMail!$D:$D,$A8) -> 0 | AG8: =SUMIFS(dataMail!$R:$R,dataMail!$C:$C,"<>Annulation",dataMail!$G:$G,"<"&AK$1,dataMail!$G:$G,">="&AG$1,dataMail!$D:$D,$A8) +SUMIFS(dataMail!$S:$S,dataMail!$C:$C,"<>Annulation",dataMail!$G:$G,"<"&AK$1,dataMail!$G:$G,">="&AG$1,dataMail!$D:$D,$A8) -> 0
B9: Moyenne | C9: =IFERROR(AVERAGEIFS(dataMail!$P:$P,dataMail!$C:$C,"<>Annulation",dataMail!$G:$G,"<"&E$1,dataMail!$G:$G,">="&C$1,dataMail!$D:$D,$A8),"-") -> - | E9: =IFERROR(AVERAGEIFS(dataMail!$P:$P,dataMail!$C:$C,"<>Annulation",dataMail!$G:$G,"<"&G$1,dataMail!$G:$G,">="&E$1,dataMail!$D:$D,$A8),"-") -> - | G9: =IFERROR(AVERAGEIFS(dataMail!$P:$P,dataMail!$C:$C,"<>Annulation",dataMail!$G:$G,"<"&I$1,dataMail!$G:$G,">="&G$1,dataMail!$D:$D,$A8),"-") -> - | I9: =IFERROR(AVERAGEIFS(dataMail!$P:$P,dataMail!$C:$C,"<>Annulation",dataMail!$G:$G,"<"&K$1,dataMail!$G:$G,">="&I$1,dataMail!$D:$D,$A8),"-") -> 143.86 | K9: =IFERROR(AVERAGEIFS(dataMail!$P:$P,dataMail!$C:$C,"<>Annulation",dataMail!$G:$G,"<"&M$1,dataMail!$G:$G,">="&K$1,dataMail!$D:$D,$A8),"-") -> 301.92 | M9: =IFERROR(AVERAGEIFS(dataMail!$P:$P,dataMail!$C:$C,"<>Annulation",dataMail!$G:$G,"<"&O$1,dataMail!$G:$G,">="&M$1,dataMail!$D:$D,$A8),"-") -> 153.248 | O9: =IFERROR(AVERAGEIFS(dataMail!$P:$P,dataMail!$C:$C,"<>Annulation",dataMail!$G:$G,"<"&Q$1,dataMail!$G:$G,">="&O$1,dataMail!$D:$D,$A8),"-") -> - | Q9: =IFERROR(AVERAGEIFS(dataMail!$P:$P,dataMail!$C:$C,"<>Annulation",dataMail!$G:$G,"<"&S$1,dataMail!$G:$G,">="&Q$1,dataMail!$D:$D,$A8),"-") -> - | S9: =IFERROR(AVERAGEIFS(dataMail!$P:$P,dataMail!$C:$C,"<>Annulation",dataMail!$G:$G,"<"&U$1,dataMail!$G:$G,">="&S$1,dataMail!$D:$D,$A8),"-") -> - | U9: =IFERROR(AVERAGEIFS(dataMail!$P:$P,dataMail!$C:$C,"<>Annulation",dataMail!$G:$G,"<"&W$1,dataMail!$G:$G,">="&U$1,dataMail!$D:$D,$A8),"-") -> - | W9: =IFERROR(AVERAGEIFS(dataMail!$P:$P,dataMail!$C:$C,"<>Annulation",dataMail!$G:$G,"<"&Y$1,dataMail!$G:$G,">="&W$1,dataMail!$D:$D,$A8),"-") -> - | Y9: =IFERROR(AVERAGEIFS(dataMail!$P:$P,dataMail!$C:$C,"<>Annulation",dataMail!$G:$G,"<"&AC$1,dataMail!$G:$G,">="&Y$1,dataMail!$D:$D,$A8),"-") -> - | AA9: =IFERROR(AVERAGEIFS(dataMail!$P:$P,dataMail!$C:$C,"<>Annulation",dataMail!$G:$G,"<"&AC$1,dataMail!$G:$G,">="&AA$1,dataMail!$D:$D,$A8),"-") -> - | AC9: =IFERROR(AVERAGEIFS(dataMail!$P:$P,dataMail!$C:$C,"<>Annulation",dataMail!$G:$G,"<"&AE$1,dataMail!$G:$G,">="&AC$1,dataMail!$D:$D,$A8),"-") -> - | AE9: =IFERROR(AVERAGEIFS(dataMail!$P:$P,dataMail!$C:$C,"<>Annulation",dataMail!$G:$G,"<"&AI$1,dataMail!$G:$G,">="&AE$1,dataMail!$D:$D,$A8),"-") -> - | AG9: =IFERROR(AVERAGEIFS(dataMail!$P:$P,dataMail!$C:$C,"<>Annulation",dataMail!$G:$G,"<"&AK$1,dataMail!$G:$G,">="&AG$1,dataMail!$D:$D,$A8),"-") -> -
B11: 1 | C11: =IF(DAY(EOMONTH(C$1,0))>=$B11,IFERROR(AVERAGEIFS(dataMail!$P:$P,dataMail!$C:$C,"Confirmation",dataMail!$G:$G,"<="&(C$1+$B11-1),dataMail!$H:$H,">"&(C$1+$B11-1)),"-"),"-") -> 122.48875 | D11: =IF(DAY(EOMONTH(C$1,0))>=$B11, 11-COUNTIFS(dataMail!$C:$C,"<>Annulation",dataMail!$G:$G,"<="&(C$1+$B11-1),dataMail!$H:$H,">"&(C$1+$B11-1)),"-") -> 2 | E11: =IF(DAY(EOMONTH(E$1,0))>=$B11,IFERROR(AVERAGEIFS(dataMail!$P:$P,dataMail!$C:$C,"Confirmation",dataMail!$G:$G,"<="&(E$1+$B11-1),dataMail!$H:$H,">"&(E$1+$B11-1)),"-"),"-") -> 161.85927 | F11: =IF(DAY(EOMONTH(E$1,0))>=$B11, 11-COUNTIFS(dataMail!$C:$C,"<>Annulation",dataMail!$G:$G,"<="&(E$1+$B11-1),dataMail!$H:$H,">"&(E$1+$B11-1)),"-") -> 3 | G11: =IF(DAY(EOMONTH(G$1,0))>=$B11,IFERROR(AVERAGEIFS(dataMail!$P:$P,dataMail!$C:$C,"Confirmation",dataMail!$G:$G,"<="&(G$1+$B11-1),dataMail!$H:$H,">"&(G$1+$B11-1)),"-"),"-") -> 96.6784 | H11: =IF(DAY(EOMONTH(G$1,0))>=$B11, 11-COUNTIFS(dataMail!$C:$C,"<>Annulation",dataMail!$G:$G,"<="&(G$1+$B11-1),dataMail!$H:$H,">"&(G$1+$B11-1)),"-") -> 1 | I11: =IF(DAY(EOMONTH(I$1,0))>=$B11,IFERROR(AVERAGEIFS(dataMail!$P:$P,dataMail!$C:$C,"Confirmation",dataMail!$G:$G,"<="&(I$1+$B11-1),dataMail!$H:$H,">"&(I$1+$B11-1)),"-"),"-") -> 126.1462 | J11: =IF(DAY(EOMONTH(I$1,0))>=$B11, 11-COUNTIFS(dataMail!$C:$C,"<>Annulation",dataMail!$G:$G,"<="&(I$1+$B11-1),dataMail!$H:$H,">"&(I$1+$B11-1)),"-") -> 1 | K11: =IF(DAY(EOMONTH(K$1,0))>=$B11,IFERROR(AVERAGEIFS(dataMail!$P:$P,dataMail!$C:$C,"Confirmation",dataMail!$G:$G,"<="&(K$1+$B11-1),dataMail!$H:$H,">"&(K$1+$B11-1)),"-"),"-") -> 132.7 | L11: =IF(DAY(EOMONTH(K$1,0))>=$B11, 11-COUNTIFS(dataMail!$C:$C,"<>Annulation",dataMail!$G:$G,"<="&(K$1+$B11-1),dataMail!$H:$H,">"&(K$1+$B11-1)),"-") -> -4 | M11: =IF(DAY(EOMONTH(M$1,0))>=$B11,IFERROR(AVERAGEIFS(dataMail!$P:$P,dataMail!$C:$C,"Confirmation",dataMail!$G:$G,"<="&(M$1+$B11-1),dataMail!$H:$H,">"&(M$1+$B11-1)),"-"),"-") -> 181.86667 | N11: =IF(DAY(EOMONTH(M$1,0))>=$B11, 11-COUNTIFS(dataMail!$C:$C,"<>Annulation",dataMail!$G:$G,"<="&(M$1+$B11-1),dataMail!$H:$H,">"&(M$1+$B11-1)),"-") -> 8 | O11: =IF(DAY(EOMONTH(O$1,0))>=$B11,IFERROR(AVERAGEIFS(dataMail!$P:$P,dataMail!$C:$C,"Confirmation",dataMail!$G:$G,"<="&(O$1+$B11-1),dataMail!$H:$H,">"&(O$1+$B11-1)),"-"),"-") -> 134.456 | P11: =IF(DAY(EOMONTH(O$1,0))>=$B11, 11-COUNTIFS(dataMail!$C:$C,"<>Annulation",dataMail!$G:$G,"<="&(O$1+$B11-1),dataMail!$H:$H,">"&(O$1+$B11-1)),"-") -> 9 | Q11: =IF(DAY(EOMONTH(Q$1,0))>=$B11,IFERROR(AVERAGEIFS(dataMail!$P:$P,dataMail!$C:$C,"Confirmation",dataMail!$G:$G,"<="&(Q$1+$B11-1),dataMail!$H:$H,">"&(Q$1+$B11-1)),"-"),"-") -> 190.13917 | R11: =IF(DAY(EOMONTH(Q$1,0))>=$B11, 11-COUNTIFS(dataMail!$C:$C,"<>Annulation",dataMail!$G:$G,"<="&(Q$1+$B11-1),dataMail!$H:$H,">"&(Q$1+$B11-1)),"-") -> 8 | S11: =IF(DAY(EOMONTH(S$1,0))>=$B11,IFERROR(AVERAGEIFS(dataMail!$P:$P,dataMail!$C:$C,"Confirmation",dataMail!$G:$G,"<="&(S$1+$B11-1),dataMail!$H:$H,">"&(S$1+$B11-1)),"-"),"-") -> 120.576 | T11: =IF(DAY(EOMONTH(S$1,0))>=$B11, 11-COUNTIFS(dataMail!$C:$C,"<>Annulation",dataMail!$G:$G,"<="&(S$1+$B11-1),dataMail!$H:$H,">"&(S$1+$B11-1)),"-") -> 10 | U11: =IF(DAY(EOMONTH(U$1,0))>=$B11,IFERROR(AVERAGEIFS(dataMail!$P:$P,dataMail!$C:$C,"Confirmation",dataMail!$G:$G,"<="&(U$1+$B11-1),dataMail!$H:$H,">"&(U$1+$B11-1)),"-"),"-") -> - | V11: =IF(DAY(EOMONTH(U$1,0))>=$B11, 11-COUNTIFS(dataMail!$C:$C,"<>Annulation",dataMail!$G:$G,"<="&(U$1+$B11-1),dataMail!$H:$H,">"&(U$1+$B11-1)),"-") -> 11 | W11: =IF(DAY(EOMONTH(W$1,0))>=$B11,IFERROR(AVERAGEIFS(dataMail!$P:$P,dataMail!$C:$C,"Confirmation",dataMail!$G:$G,"<="&(W$1+$B11-1),dataMail!$H:$H,">"&(W$1+$B11-1)),"-"),"-") -> 146.868 | X11: =IF(DAY(EOMONTH(W$1,0))>=$B11, 11-COUNTIFS(dataMail!$C:$C,"<>Annulation",dataMail!$G:$G,"<="&(W$1+$B11-1),dataMail!$H:$H,">"&(W$1+$B11-1)),"-") -> 9 | Y11: =IF(DAY(EOMONTH(Y$1,0))>=$B11,IFERROR(AVERAGEIFS(dataMail!$P:$P,dataMail!$C:$C,"Confirmation",dataMail!$G:$G,"<="&(Y$1+$B11-1),dataMail!$H:$H,">"&(Y$1+$B11-1)),"-"),"-") -> - | Z11: =IF(DAY(EOMONTH(Y$1,0))>=$B11, 11-COUNTIFS(dataMail!$C:$C,"<>Annulation",dataMail!$G:$G,"<="&(Y$1+$B11-1),dataMail!$H:$H,">"&(Y$1+$B11-1)),"-") -> 11 | AA11: =IF(DAY(EOMONTH(AA$1,0))>=$B11,IFERROR(AVERAGEIFS(dataMail!$P:$P,dataMail!$C:$C,"Confirmation",dataMail!$G:$G,"<="&(AA$1+$B11-1),dataMail!$H:$H,">"&(AA$1+$B11-1)),"-"),"-") -> - | AB11: =IF(DAY(EOMONTH(AA$1,0))>=$B11, 11-COUNTIFS(dataMail!$C:$C,"<>Annulation",dataMail!$G:$G,"<="&(AA$1+$B11-1),dataMail!$H:$H,">"&(AA$1+$B11-1)),"-") -> 11 | AC11: =IF(DAY(EOMONTH(AC$1,0))>=$B11,IFERROR(AVERAGEIFS(dataMail!$P:$P,dataMail!$C:$C,"Confirmation",dataMail!$G:$G,"<="&(AC$1+$B11-1),dataMail!$H:$H,">"&(AC$1+$B11-1)),"-"),"-") -> - | AD11: =IF(DAY(EOMONTH(AC$1,0))>=$B11, 11-COUNTIFS(dataMail!$C:$C,"<>Annulation",dataMail!$G:$G,"<="&(AC$1+$B11-1),dataMail!$H:$H,">"&(AC$1+$B11-1)),"-") -> 11 | AE11: =IF(DAY(EOMONTH(AE$1,0))>=$B11,IFERROR(AVERAGEIFS(dataMail!$P:$P,dataMail!$C:$C,"Confirmation",dataMail!$G:$G,"<="&(AE$1+$B11-1),dataMail!$H:$H,">"&(AE$1+$B11-1)),"-"),"-") -> - | AF11: =IF(DAY(EOMONTH(AE$1,0))>=$B11, 11-COUNTIFS(dataMail!$C:$C,"<>Annulation",dataMail!$G:$G,"<="&(AE$1+$B11-1),dataMail!$H:$H,">"&(AE$1+$B11-1)),"-") -> 11 | AG11: =IF(DAY(EOMONTH(AG$1,0))>=$B11,IFERROR(AVERAGEIFS(dataMail!$P:$P,dataMail!$C:$C,"Confirmation",dataMail!$G:$G,"<="&(AG$1+$B11-1),dataMail!$H:$H,">"&(AG$1+$B11-1)),"-"),"-") -> 115.312 | AH11: =IF(DAY(EOMONTH(AG$1,0))>=$B11, 11-COUNTIFS(dataMail!$C:$C,"<>Annulation",dataMail!$G:$G,"<="&(AG$1+$B11-1),dataMail!$H:$H,">"&(AG$1+$B11-1)),"-") -> 10
B12: 2 | C12: =IF(DAY(EOMONTH(C$1,0))>=$B12,IFERROR(AVERAGEIFS(dataMail!$P:$P,dataMail!$C:$C,"Confirmation",dataMail!$G:$G,"<="&(C$1+$B12-1),dataMail!$H:$H,">"&(C$1+$B12-1)),"-"),"-") -> 108.44118 | D12: =IF(DAY(EOMONTH(C$1,0))>=$B12, 11-COUNTIFS(dataMail!$C:$C,"<>Annulation",dataMail!$G:$G,"<="&(C$1+$B12-1),dataMail!$H:$H,">"&(C$1+$B12-1)),"-") -> 3 | E12: =IF(DAY(EOMONTH(E$1,0))>=$B12,IFERROR(AVERAGEIFS(dataMail!$P:$P,dataMail!$C:$C,"Confirmation",dataMail!$G:$G,"<="&(E$1+$B12-1),dataMail!$H:$H,">"&(E$1+$B12-1)),"-"),"-") -> 178.6824 | F12: =IF(DAY(EOMONTH(E$1,0))>=$B12, 11-COUNTIFS(dataMail!$C:$C,"<>Annulation",dataMail!$G:$G,"<="&(E$1+$B12-1),dataMail!$H:$H,">"&(E$1+$B12-1)),"-") -> 5 | G12: =IF(DAY(EOMONTH(G$1,0))>=$B12,IFERROR(AVERAGEIFS(dataMail!$P:$P,dataMail!$C:$C,"Confirmation",dataMail!$G:$G,"<="&(G$1+$B12-1),dataMail!$H:$H,">"&(G$1+$B12-1)),"-"),"-") -> 109.736 | H12: =IF(DAY(EOMONTH(G$1,0))>=$B12, 11-COUNTIFS(dataMail!$C:$C,"<>Annulation",dataMail!$G:$G,"<="&(G$1+$B12-1),dataMail!$H:$H,">"&(G$1+$B12-1)),"-") -> 4 | I12: =IF(DAY(EOMONTH(I$1,0))>=$B12,IFERROR(AVERAGEIFS(dataMail!$P:$P,dataMail!$C:$C,"Confirmation",dataMail!$G:$G,"<="&(I$1+$B12-1),dataMail!$H:$H,">"&(I$1+$B12-1)),"-"),"-") -> 130.3198 | J12: =IF(DAY(EOMONTH(I$1,0))>=$B12, 11-COUNTIFS(dataMail!$C:$C,"<>Annulation",dataMail!$G:$G,"<="&(I$1+$B12-1),dataMail!$H:$H,">"&(I$1+$B12-1)),"-") -> 0 | K12: =IF(DAY(EOMONTH(K$1,0))>=$B12,IFERROR(AVERAGEIFS(dataMail!$P:$P,dataMail!$C:$C,"Confirmation",dataMail!$G:$G,"<="&(K$1+$B12-1),dataMail!$H:$H,">"&(K$1+$B12-1)),"-"),"-") -> 133.504 | L12: =IF(DAY(EOMONTH(K$1,0))>=$B12, 11-COUNTIFS(dataMail!$C:$C,"<>Annulation",dataMail!$G:$G,"<="&(K$1+$B12-1),dataMail!$H:$H,">"&(K$1+$B12-1)),"-") -> -2 | M12: =IF(DAY(EOMONTH(M$1,0))>=$B12,IFERROR(AVERAGEIFS(dataMail!$P:$P,dataMail!$C:$C,"Confirmation",dataMail!$G:$G,"<="&(M$1+$B12-1),dataMail!$H:$H,">"&(M$1+$B12-1)),"-"),"-") -> 148.30743 | N12: =IF(DAY(EOMONTH(M$1,0))>=$B12, 11-COUNTIFS(dataMail!$C:$C,"<>Annulation",dataMail!$G:$G,"<="&(M$1+$B12-1),dataMail!$H:$H,">"&(M$1+$B12-1)),"-") -> 4 | O12: =IF(DAY(EOMONTH(O$1,0))>=$B12,IFERROR(AVERAGEIFS(dataMail!$P:$P,dataMail!$C:$C,"Confirmation",dataMail!$G:$G,"<="&(O$1+$B12-1),dataMail!$H:$H,">"&(O$1+$B12-1)),"-"),"-") -> 206.768 | P12: =IF(DAY(EOMONTH(O$1,0))>=$B12, 11-COUNTIFS(dataMail!$C:$C,"<>Annulation",dataMail!$G:$G,"<="&(O$1+$B12-1),dataMail!$H:$H,">"&(O$1+$B12-1)),"-") -> 7 | Q12: =IF(DAY(EOMONTH(Q$1,0))>=$B12,IFERROR(AVERAGEIFS(dataMail!$P:$P,dataMail!$C:$C,"Confirmation",dataMail!$G:$G,"<="&(Q$1+$B12-1),dataMail!$H:$H,">"&(Q$1+$B12-1)),"-"),"-") -> 214.67437 | R12: =IF(DAY(EOMONTH(Q$1,0))>=$B12, 11-COUNTIFS(dataMail!$C:$C,"<>Annulation",dataMail!$G:$G,"<="&(Q$1+$B12-1),dataMail!$H:$H,">"&(Q$1+$B12-1)),"-") -> 7 | S12: =IF(DAY(EOMONTH(S$1,0))>=$B12,IFERROR(AVERAGEIFS(dataMail!$P:$P,dataMail!$C:$C,"Confirmation",dataMail!$G:$G,"<="&(S$1+$B12-1),dataMail!$H:$H,">"&(S$1+$B12-1)),"-"),"-") -> 120.576 | T12: =IF(DAY(EOMONTH(S$1,0))>=$B12, 11-COUNTIFS(dataMail!$C:$C,"<>Annulation",dataMail!$G:$G,"<="&(S$1+$B12-1),dataMail!$H:$H,">"&(S$1+$B12-1)),"-") -> 9 | U12: =IF(DAY(EOMONTH(U$1,0))>=$B12,IFERROR(AVERAGEIFS(dataMail!$P:$P,dataMail!$C:$C,"Confirmation",dataMail!$G:$G,"<="&(U$1+$B12-1),dataMail!$H:$H,">"&(U$1+$B12-1)),"-"),"-") -> - | V12: =IF(DAY(EOMONTH(U$1,0))>=$B12, 11-COUNTIFS(dataMail!$C:$C,"<>Annulation",dataMail!$G:$G,"<="&(U$1+$B12-1),dataMail!$H:$H,">"&(U$1+$B12-1)),"-") -> 11 | W12: =IF(DAY(EOMONTH(W$1,0))>=$B12,IFERROR(AVERAGEIFS(dataMail!$P:$P,dataMail!$C:$C,"Confirmation",dataMail!$G:$G,"<="&(W$1+$B12-1),dataMail!$H:$H,">"&(W$1+$B12-1)),"-"),"-") -> 167.2912 | X12: =IF(DAY(EOMONTH(W$1,0))>=$B12, 11-COUNTIFS(dataMail!$C:$C,"<>Annulation",dataMail!$G:$G,"<="&(W$1+$B12-1),dataMail!$H:$H,">"&(W$1+$B12-1)),"-") -> 8 | Y12: =IF(DAY(EOMONTH(Y$1,0))>=$B12,IFERROR(AVERAGEIFS(dataMail!$P:$P,dataMail!$C:$C,"Confirmation",dataMail!$G:$G,"<="&(Y$1+$B12-1),dataMail!$H:$H,">"&(Y$1+$B12-1)),"-"),"-") -> - | Z12: =IF(DAY(EOMONTH(Y$1,0))>=$B12, 11-COUNTIFS(dataMail!$C:$C,"<>Annulation",dataMail!$G:$G,"<="&(Y$1+$B12-1),dataMail!$H:$H,">"&(Y$1+$B12-1)),"-") -> 11 | AA12: =IF(DAY(EOMONTH(AA$1,0))>=$B12,IFERROR(AVERAGEIFS(dataMail!$P:$P,dataMail!$C:$C,"Confirmation",dataMail!$G:$G,"<="&(AA$1+$B12-1),dataMail!$H:$H,">"&(AA$1+$B12-1)),"-"),"-") -> - | AB12: =IF(DAY(EOMONTH(AA$1,0))>=$B12, 11-COUNTIFS(dataMail!$C:$C,"<>Annulation",dataMail!$G:$G,"<="&(AA$1+$B12-1),dataMail!$H:$H,">"&(AA$1+$B12-1)),"-") -> 11 | AC12: =IF(DAY(EOMONTH(AC$1,0))>=$B12,IFERROR(AVERAGEIFS(dataMail!$P:$P,dataMail!$C:$C,"Confirmation",dataMail!$G:$G,"<="&(AC$1+$B12-1),dataMail!$H:$H,">"&(AC$1+$B12-1)),"-"),"-") -> - | AD12: =IF(DAY(EOMONTH(AC$1,0))>=$B12, 11-COUNTIFS(dataMail!$C:$C,"<>Annulation",dataMail!$G:$G,"<="&(AC$1+$B12-1),dataMail!$H:$H,">"&(AC$1+$B12-1)),"-") -> 11 | AE12: =IF(DAY(EOMONTH(AE$1,0))>=$B12,IFERROR(AVERAGEIFS(dataMail!$P:$P,dataMail!$C:$C,"Confirmation",dataMail!$G:$G,"<="&(AE$1+$B12-1),dataMail!$H:$H,">"&(AE$1+$B12-1)),"-"),"-") -> - | AF12: =IF(DAY(EOMONTH(AE$1,0))>=$B12, 11-COUNTIFS(dataMail!$C:$C,"<>Annulation",dataMail!$G:$G,"<="&(AE$1+$B12-1),dataMail!$H:$H,">"&(AE$1+$B12-1)),"-") -> 11 | AG12: =IF(DAY(EOMONTH(AG$1,0))>=$B12,IFERROR(AVERAGEIFS(dataMail!$P:$P,dataMail!$C:$C,"Confirmation",dataMail!$G:$G,"<="&(AG$1+$B12-1),dataMail!$H:$H,">"&(AG$1+$B12-1)),"-"),"-") -> - | AH12: =IF(DAY(EOMONTH(AG$1,0))>=$B12, 11-COUNTIFS(dataMail!$C:$C,"<>Annulation",dataMail!$G:$G,"<="&(AG$1+$B12-1),dataMail!$H:$H,">"&(AG$1+$B12-1)),"-") -> 11
B13: 3 | C13: =IF(DAY(EOMONTH(C$1,0))>=$B13,IFERROR(AVERAGEIFS(dataMail!$P:$P,dataMail!$C:$C,"Confirmation",dataMail!$G:$G,"<="&(C$1+$B13-1),dataMail!$H:$H,">"&(C$1+$B13-1)),"-"),"-") -> 108.90238 | D13: =IF(DAY(EOMONTH(C$1,0))>=$B13, 11-COUNTIFS(dataMail!$C:$C,"<>Annulation",dataMail!$G:$G,"<="&(C$1+$B13-1),dataMail!$H:$H,">"&(C$1+$B13-1)),"-") -> 2 | E13: =IF(DAY(EOMONTH(E$1,0))>=$B13,IFERROR(AVERAGEIFS(dataMail!$P:$P,dataMail!$C:$C,"Confirmation",dataMail!$G:$G,"<="&(E$1+$B13-1),dataMail!$H:$H,">"&(E$1+$B13-1)),"-"),"-") -> 134.41493 | F13: =IF(DAY(EOMONTH(E$1,0))>=$B13, 11-COUNTIFS(dataMail!$C:$C,"<>Annulation",dataMail!$G:$G,"<="&(E$1+$B13-1),dataMail!$H:$H,">"&(E$1+$B13-1)),"-") -> 5 | G13: =IF(DAY(EOMONTH(G$1,0))>=$B13,IFERROR(AVERAGEIFS(dataMail!$P:$P,dataMail!$C:$C,"Confirmation",dataMail!$G:$G,"<="&(G$1+$B13-1),dataMail!$H:$H,">"&(G$1+$B13-1)),"-"),"-") -> 94.092571 | H13: =IF(DAY(EOMONTH(G$1,0))>=$B13, 11-COUNTIFS(dataMail!$C:$C,"<>Annulation",dataMail!$G:$G,"<="&(G$1+$B13-1),dataMail!$H:$H,">"&(G$1+$B13-1)),"-") -> 4 | I13: =IF(DAY(EOMONTH(I$1,0))>=$B13,IFERROR(AVERAGEIFS(dataMail!$P:$P,dataMail!$C:$C,"Confirmation",dataMail!$G:$G,"<="&(I$1+$B13-1),dataMail!$H:$H,">"&(I$1+$B13-1)),"-"),"-") -> 109.50275 | J13: =IF(DAY(EOMONTH(I$1,0))>=$B13, 11-COUNTIFS(dataMail!$C:$C,"<>Annulation",dataMail!$G:$G,"<="&(I$1+$B13-1),dataMail!$H:$H,">"&(I$1+$B13-1)),"-") -> 2 | K13: =IF(DAY(EOMONTH(K$1,0))>=$B13,IFERROR(AVERAGEIFS(dataMail!$P:$P,dataMail!$C:$C,"Confirmation",dataMail!$G:$G,"<="&(K$1+$B13-1),dataMail!$H:$H,">"&(K$1+$B13-1)),"-"),"-") -> 130.01867 | L13: =IF(DAY(EOMONTH(K$1,0))>=$B13, 11-COUNTIFS(dataMail!$C:$C,"<>Annulation",dataMail!$G:$G,"<="&(K$1+$B13-1),dataMail!$H:$H,">"&(K$1+$B13-1)),"-") -> 4 | M13: =IF(DAY(EOMONTH(M$1,0))>=$B13,IFERROR(AVERAGEIFS(dataMail!$P:$P,dataMail!$C:$C,"Confirmation",dataMail!$G:$G,"<="&(M$1+$B13-1),dataMail!$H:$H,">"&(M$1+$B13-1)),"-"),"-") -> 156.10514 | N13: =IF(DAY(EOMONTH(M$1,0))>=$B13, 11-COUNTIFS(dataMail!$C:$C,"<>Annulation",dataMail!$G:$G,"<="&(M$1+$B13-1),dataMail!$H:$H,">"&(M$1+$B13-1)),"-") -> 3 | O13: =IF(DAY(EOMONTH(O$1,0))>=$B13,IFERROR(AVERAGEIFS(dataMail!$P:$P,dataMail!$C:$C,"Confirmation",dataMail!$G:$G,"<="&(O$1+$B13-1),dataMail!$H:$H,">"&(O$1+$B13-1)),"-"),"-") -> 206.768 | P13: =IF(DAY(EOMONTH(O$1,0))>=$B13, 11-COUNTIFS(dataMail!$C:$C,"<>Annulation",dataMail!$G:$G,"<="&(O$1+$B13-1),dataMail!$H:$H,">"&(O$1+$B13-1)),"-") -> 7 | Q13: =IF(DAY(EOMONTH(Q$1,0))>=$B13,IFERROR(AVERAGEIFS(dataMail!$P:$P,dataMail!$C:$C,"Confirmation",dataMail!$G:$G,"<="&(Q$1+$B13-1),dataMail!$H:$H,">"&(Q$1+$B13-1)),"-"),"-") -> 187.168 | R13: =IF(DAY(EOMONTH(Q$1,0))>=$B13, 11-COUNTIFS(dataMail!$C:$C,"<>Annulation",dataMail!$G:$G,"<="&(Q$1+$B13-1),dataMail!$H:$H,">"&(Q$1+$B13-1)),"-") -> 6 | S13: =IF(DAY(EOMONTH(S$1,0))>=$B13,IFERROR(AVERAGEIFS(dataMail!$P:$P,dataMail!$C:$C,"Confirmation",dataMail!$G:$G,"<="&(S$1+$B13-1),dataMail!$H:$H,">"&(S$1+$B13-1)),"-"),"-") -> - | T13: =IF(DAY(EOMONTH(S$1,0))>=$B13, 11-COUNTIFS(dataMail!$C:$C,"<>Annulation",dataMail!$G:$G,"<="&(S$1+$B13-1),dataMail!$H:$H,">"&(S$1+$B13-1)),"-") -> 10 | U13: =IF(DAY(EOMONTH(U$1,0))>=$B13,IFERROR(AVERAGEIFS(dataMail!$P:$P,dataMail!$C:$C,"Confirmation",dataMail!$G:$G,"<="&(U$1+$B13-1),dataMail!$H:$H,">"&(U$1+$B13-1)),"-"),"-") -> - | V13: =IF(DAY(EOMONTH(U$1,0))>=$B13, 11-COUNTIFS(dataMail!$C:$C,"<>Annulation",dataMail!$G:$G,"<="&(U$1+$B13-1),dataMail!$H:$H,">"&(U$1+$B13-1)),"-") -> 11 | W13: =IF(DAY(EOMONTH(W$1,0))>=$B13,IFERROR(AVERAGEIFS(dataMail!$P:$P,dataMail!$C:$C,"Confirmation",dataMail!$G:$G,"<="&(W$1+$B13-1),dataMail!$H:$H,">"&(W$1+$B13-1)),"-"),"-") -> 146.868 | X13: =IF(DAY(EOMONTH(W$1,0))>=$B13, 11-COUNTIFS(dataMail!$C:$C,"<>Annulation",dataMail!$G:$G,"<="&(W$1+$B13-1),dataMail!$H:$H,">"&(W$1+$B13-1)),"-") -> 9 | Y13: =IF(DAY(EOMONTH(Y$1,0))>=$B13,IFERROR(AVERAGEIFS(dataMail!$P:$P,dataMail!$C:$C,"Confirmation",dataMail!$G:$G,"<="&(Y$1+$B13-1),dataMail!$H:$H,">"&(Y$1+$B13-1)),"-"),"-") -> - | Z13: =IF(DAY(EOMONTH(Y$1,0))>=$B13, 11-COUNTIFS(dataMail!$C:$C,"<>Annulation",dataMail!$G:$G,"<="&(Y$1+$B13-1),dataMail!$H:$H,">"&(Y$1+$B13-1)),"-") -> 11 | AA13: =IF(DAY(EOMONTH(AA$1,0))>=$B13,IFERROR(AVERAGEIFS(dataMail!$P:$P,dataMail!$C:$C,"Confirmation",dataMail!$G:$G,"<="&(AA$1+$B13-1),dataMail!$H:$H,">"&(AA$1+$B13-1)),"-"),"-") -> 94.8 | AB13: =IF(DAY(EOMONTH(AA$1,0))>=$B13, 11-COUNTIFS(dataMail!$C:$C,"<>Annulation",dataMail!$G:$G,"<="&(AA$1+$B13-1),dataMail!$H:$H,">"&(AA$1+$B13-1)),"-") -> 9 | AC13: =IF(DAY(EOMONTH(AC$1,0))>=$B13,IFERROR(AVERAGEIFS(dataMail!$P:$P,dataMail!$C:$C,"Confirmation",dataMail!$G:$G,"<="&(AC$1+$B13-1),dataMail!$H:$H,">"&(AC$1+$B13-1)),"-"),"-") -> - | AD13: =IF(DAY(EOMONTH(AC$1,0))>=$B13, 11-COUNTIFS(dataMail!$C:$C,"<>Annulation",dataMail!$G:$G,"<="&(AC$1+$B13-1),dataMail!$H:$H,">"&(AC$1+$B13-1)),"-") -> 11 | AE13: =IF(DAY(EOMONTH(AE$1,0))>=$B13,IFERROR(AVERAGEIFS(dataMail!$P:$P,dataMail!$C:$C,"Confirmation",dataMail!$G:$G,"<="&(AE$1+$B13-1),dataMail!$H:$H,">"&(AE$1+$B13-1)),"-"),"-") -> - | AF13: =IF(DAY(EOMONTH(AE$1,0))>=$B13, 11-COUNTIFS(dataMail!$C:$C,"<>Annulation",dataMail!$G:$G,"<="&(AE$1+$B13-1),dataMail!$H:$H,">"&(AE$1+$B13-1)),"-") -> 11 | AG13: =IF(DAY(EOMONTH(AG$1,0))>=$B13,IFERROR(AVERAGEIFS(dataMail!$P:$P,dataMail!$C:$C,"Confirmation",dataMail!$G:$G,"<="&(AG$1+$B13-1),dataMail!$H:$H,">"&(AG$1+$B13-1)),"-"),"-") -> - | AH13: =IF(DAY(EOMONTH(AG$1,0))>=$B13, 11-COUNTIFS(dataMail!$C:$C,"<>Annulation",dataMail!$G:$G,"<="&(AG$1+$B13-1),dataMail!$H:$H,">"&(AG$1+$B13-1)),"-") -> 11
B14: 4 | C14: =IF(DAY(EOMONTH(C$1,0))>=$B14,IFERROR(AVERAGEIFS(dataMail!$P:$P,dataMail!$C:$C,"Confirmation",dataMail!$G:$G,"<="&(C$1+$B14-1),dataMail!$H:$H,">"&(C$1+$B14-1)),"-"),"-") -> 103.50192 | D14: =IF(DAY(EOMONTH(C$1,0))>=$B14, 11-COUNTIFS(dataMail!$C:$C,"<>Annulation",dataMail!$G:$G,"<="&(C$1+$B14-1),dataMail!$H:$H,">"&(C$1+$B14-1)),"-") -> 4 | E14: =IF(DAY(EOMONTH(E$1,0))>=$B14,IFERROR(AVERAGEIFS(dataMail!$P:$P,dataMail!$C:$C,"Confirmation",dataMail!$G:$G,"<="&(E$1+$B14-1),dataMail!$H:$H,">"&(E$1+$B14-1)),"-"),"-") -> 139.0968 | F14: =IF(DAY(EOMONTH(E$1,0))>=$B14, 11-COUNTIFS(dataMail!$C:$C,"<>Annulation",dataMail!$G:$G,"<="&(E$1+$B14-1),dataMail!$H:$H,">"&(E$1+$B14-1)),"-") -> 1 | G14: =IF(DAY(EOMONTH(G$1,0))>=$B14,IFERROR(AVERAGEIFS(dataMail!$P:$P,dataMail!$C:$C,"Confirmation",dataMail!$G:$G,"<="&(G$1+$B14-1),dataMail!$H:$H,">"&(G$1+$B14-1)),"-"),"-") -> 93.4936 | H14: =IF(DAY(EOMONTH(G$1,0))>=$B14, 11-COUNTIFS(dataMail!$C:$C,"<>Annulation",dataMail!$G:$G,"<="&(G$1+$B14-1),dataMail!$H:$H,">"&(G$1+$B14-1)),"-") -> 1 | I14: =IF(DAY(EOMONTH(I$1,0))>=$B14,IFERROR(AVERAGEIFS(dataMail!$P:$P,dataMail!$C:$C,"Confirmation",dataMail!$G:$G,"<="&(I$1+$B14-1),dataMail!$H:$H,">"&(I$1+$B14-1)),"-"),"-") -> 124.812 | J14: =IF(DAY(EOMONTH(I$1,0))>=$B14, 11-COUNTIFS(dataMail!$C:$C,"<>Annulation",dataMail!$G:$G,"<="&(I$1+$B14-1),dataMail!$H:$H,">"&(I$1+$B14-1)),"-") -> 7 | K14: =IF(DAY(EOMONTH(K$1,0))>=$B14,IFERROR(AVERAGEIFS(dataMail!$P:$P,dataMail!$C:$C,"Confirmation",dataMail!$G:$G,"<="&(K$1+$B14-1),dataMail!$H:$H,">"&(K$1+$B14-1)),"-"),"-") -> 135.06795 | L14: =IF(DAY(EOMONTH(K$1,0))>=$B14, 11-COUNTIFS(dataMail!$C:$C,"<>Annulation",dataMail!$G:$G,"<="&(K$1+$B14-1),dataMail!$H:$H,">"&(K$1+$B14-1)),"-") -> -1 | M14: =IF(DAY(EOMONTH(M$1,0))>=$B14,IFERROR(AVERAGEIFS(dataMail!$P:$P,dataMail!$C:$C,"Confirmation",dataMail!$G:$G,"<="&(M$1+$B14-1),dataMail!$H:$H,">"&(M$1+$B14-1)),"-"),"-") -> 165.344 | N14: =IF(DAY(EOMONTH(M$1,0))>=$B14, 11-COUNTIFS(dataMail!$C:$C,"<>Annulation",dataMail!$G:$G,"<="&(M$1+$B14-1),dataMail!$H:$H,">"&(M$1+$B14-1)),"-") -> 4 | O14: =IF(DAY(EOMONTH(O$1,0))>=$B14,IFERROR(AVERAGEIFS(dataMail!$P:$P,dataMail!$C:$C,"Confirmation",dataMail!$G:$G,"<="&(O$1+$B14-1),dataMail!$H:$H,">"&(O$1+$B14-1)),"-"),"-") -> 266.796 | P14: =IF(DAY(EOMONTH(O$1,0))>=$B14, 11-COUNTIFS(dataMail!$C:$C,"<>Annulation",dataMail!$G:$G,"<="&(O$1+$B14-1),dataMail!$H:$H,">"&(O$1+$B14-1)),"-") -> 9 | Q14: =IF(DAY(EOMONTH(Q$1,0))>=$B14,IFERROR(AVERAGEIFS(dataMail!$P:$P,dataMail!$C:$C,"Confirmation",dataMail!$G:$G,"<="&(Q$1+$B14-1),dataMail!$H:$H,">"&(Q$1+$B14-1)),"-"),"-") -> 229.28 | R14: =IF(DAY(EOMONTH(Q$1,0))>=$B14, 11-COUNTIFS(dataMail!$C:$C,"<>Annulation",dataMail!$G:$G,"<="&(Q$1+$B14-1),dataMail!$H:$H,">"&(Q$1+$B14-1)),"-") -> 0 | S14: =IF(DAY(EOMONTH(S$1,0))>=$B14,IFERROR(AVERAGEIFS(dataMail!$P:$P,dataMail!$C:$C,"Confirmation",dataMail!$G:$G,"<="&(S$1+$B14-1),dataMail!$H:$H,">"&(S$1+$B14-1)),"-"),"-") -> - | T14: =IF(DAY(EOMONTH(S$1,0))>=$B14, 11-COUNTIFS(dataMail!$C:$C,"<>Annulation",dataMail!$G:$G,"<="&(S$1+$B14-1),dataMail!$H:$H,">"&(S$1+$B14-1)),"-") -> 10 | U14: =IF(DAY(EOMONTH(U$1,0))>=$B14,IFERROR(AVERAGEIFS(dataMail!$P:$P,dataMail!$C:$C,"Confirmation",dataMail!$G:$G,"<="&(U$1+$B14-1),dataMail!$H:$H,">"&(U$1+$B14-1)),"-"),"-") -> 147.096 | V14: =IF(DAY(EOMONTH(U$1,0))>=$B14, 11-COUNTIFS(dataMail!$C:$C,"<>Annulation",dataMail!$G:$G,"<="&(U$1+$B14-1),dataMail!$H:$H,">"&(U$1+$B14-1)),"-") -> 10 | W14: =IF(DAY(EOMONTH(W$1,0))>=$B14,IFERROR(AVERAGEIFS(dataMail!$P:$P,dataMail!$C:$C,"Confirmation",dataMail!$G:$G,"<="&(W$1+$B14-1),dataMail!$H:$H,">"&(W$1+$B14-1)),"-"),"-") -> - | X14: =IF(DAY(EOMONTH(W$1,0))>=$B14, 11-COUNTIFS(dataMail!$C:$C,"<>Annulation",dataMail!$G:$G,"<="&(W$1+$B14-1),dataMail!$H:$H,">"&(W$1+$B14-1)),"-") -> 11 | Y14: =IF(DAY(EOMONTH(Y$1,0))>=$B14,IFERROR(AVERAGEIFS(dataMail!$P:$P,dataMail!$C:$C,"Confirmation",dataMail!$G:$G,"<="&(Y$1+$B14-1),dataMail!$H:$H,">"&(Y$1+$B14-1)),"-"),"-") -> 199.392 | Z14: =IF(DAY(EOMONTH(Y$1,0))>=$B14, 11-COUNTIFS(dataMail!$C:$C,"<>Annulation",dataMail!$G:$G,"<="&(Y$1+$B14-1),dataMail!$H:$H,">"&(Y$1+$B14-1)),"-") -> 9 | AA14: =IF(DAY(EOMONTH(AA$1,0))>=$B14,IFERROR(AVERAGEIFS(dataMail!$P:$P,dataMail!$C:$C,"Confirmation",dataMail!$G:$G,"<="&(AA$1+$B14-1),dataMail!$H:$H,">"&(AA$1+$B14-1)),"-"),"-") -> 94.8 | AB14: =IF(DAY(EOMONTH(AA$1,0))>=$B14, 11-COUNTIFS(dataMail!$C:$C,"<>Annulation",dataMail!$G:$G,"<="&(AA$1+$B14-1),dataMail!$H:$H,">"&(AA$1+$B14-1)),"-") -> 9 | AC14: =IF(DAY(EOMONTH(AC$1,0))>=$B14,IFERROR(AVERAGEIFS(dataMail!$P:$P,dataMail!$C:$C,"Confirmation",dataMail!$G:$G,"<="&(AC$1+$B14-1),dataMail!$H:$H,">"&(AC$1+$B14-1)),"-"),"-") -> - | AD14: =IF(DAY(EOMONTH(AC$1,0))>=$B14, 11-COUNTIFS(dataMail!$C:$C,"<>Annulation",dataMail!$G:$G,"<="&(AC$1+$B14-1),dataMail!$H:$H,">"&(AC$1+$B14-1)),"-") -> 11 | AE14: =IF(DAY(EOMONTH(AE$1,0))>=$B14,IFERROR(AVERAGEIFS(dataMail!$P:$P,dataMail!$C:$C,"Confirmation",dataMail!$G:$G,"<="&(AE$1+$B14-1),dataMail!$H:$H,">"&(AE$1+$B14-1)),"-"),"-") -> 94.624 | AF14: =IF(DAY(EOMONTH(AE$1,0))>=$B14, 11-COUNTIFS(dataMail!$C:$C,"<>Annulation",dataMail!$G:$G,"<="&(AE$1+$B14-1),dataMail!$H:$H,">"&(AE$1+$B14-1)),"-") -> 10 | AG14: =IF(DAY(EOMONTH(AG$1,0))>=$B14,IFERROR(AVERAGEIFS(dataMail!$P:$P,dataMail!$C:$C,"Confirmation",dataMail!$G:$G,"<="&(AG$1+$B14-1),dataMail!$H:$H,">"&(AG$1+$B14-1)),"-"),"-") -> - | AH14: =IF(DAY(EOMONTH(AG$1,0))>=$B14, 11-COUNTIFS(dataMail!$C:$C,"<>Annulation",dataMail!$G:$G,"<="&(AG$1+$B14-1),dataMail!$H:$H,">"&(AG$1+$B14-1)),"-") -> 11
B15: 5 | C15: =IF(DAY(EOMONTH(C$1,0))>=$B15,IFERROR(AVERAGEIFS(dataMail!$P:$P,dataMail!$C:$C,"Confirmation",dataMail!$G:$G,"<="&(C$1+$B15-1),dataMail!$H:$H,">"&(C$1+$B15-1)),"-"),"-") -> 131.9574 | D15: =IF(DAY(EOMONTH(C$1,0))>=$B15, 11-COUNTIFS(dataMail!$C:$C,"<>Annulation",dataMail!$G:$G,"<="&(C$1+$B15-1),dataMail!$H:$H,">"&(C$1+$B15-1)),"-") -> 0 | E15: =IF(DAY(EOMONTH(E$1,0))>=$B15,IFERROR(AVERAGEIFS(dataMail!$P:$P,dataMail!$C:$C,"Confirmation",dataMail!$G:$G,"<="&(E$1+$B15-1),dataMail!$H:$H,">"&(E$1+$B15-1)),"-"),"-") -> 142.60711 | F15: =IF(DAY(EOMONTH(E$1,0))>=$B15, 11-COUNTIFS(dataMail!$C:$C,"<>Annulation",dataMail!$G:$G,"<="&(E$1+$B15-1),dataMail!$H:$H,">"&(E$1+$B15-1)),"-") -> 2 | G15: =IF(DAY(EOMONTH(G$1,0))>=$B15,IFERROR(AVERAGEIFS(dataMail!$P:$P,dataMail!$C:$C,"Confirmation",dataMail!$G:$G,"<="&(G$1+$B15-1),dataMail!$H:$H,">"&(G$1+$B15-1)),"-"),"-") -> 100.8728 | H15: =IF(DAY(EOMONTH(G$1,0))>=$B15, 11-COUNTIFS(dataMail!$C:$C,"<>Annulation",dataMail!$G:$G,"<="&(G$1+$B15-1),dataMail!$H:$H,">"&(G$1+$B15-1)),"-") -> 1 | I15: =IF(DAY(EOMONTH(I$1,0))>=$B15,IFERROR(AVERAGEIFS(dataMail!$P:$P,dataMail!$C:$C,"Confirmation",dataMail!$G:$G,"<="&(I$1+$B15-1),dataMail!$H:$H,">"&(I$1+$B15-1)),"-"),"-") -> 120.13829 | J15: =IF(DAY(EOMONTH(I$1,0))>=$B15, 11-COUNTIFS(dataMail!$C:$C,"<>Annulation",dataMail!$G:$G,"<="&(I$1+$B15-1),dataMail!$H:$H,">"&(I$1+$B15-1)),"-") -> 2 | K15: =IF(DAY(EOMONTH(K$1,0))>=$B15,IFERROR(AVERAGEIFS(dataMail!$P:$P,dataMail!$C:$C,"Confirmation",dataMail!$G:$G,"<="&(K$1+$B15-1),dataMail!$H:$H,">"&(K$1+$B15-1)),"-"),"-") -> 124.248 | L15: =IF(DAY(EOMONTH(K$1,0))>=$B15, 11-COUNTIFS(dataMail!$C:$C,"<>Annulation",dataMail!$G:$G,"<="&(K$1+$B15-1),dataMail!$H:$H,">"&(K$1+$B15-1)),"-") -> 6 | M15: =IF(DAY(EOMONTH(M$1,0))>=$B15,IFERROR(AVERAGEIFS(dataMail!$P:$P,dataMail!$C:$C,"Confirmation",dataMail!$G:$G,"<="&(M$1+$B15-1),dataMail!$H:$H,">"&(M$1+$B15-1)),"-"),"-") -> 150.97143 | N15: =IF(DAY(EOMONTH(M$1,0))>=$B15, 11-COUNTIFS(dataMail!$C:$C,"<>Annulation",dataMail!$G:$G,"<="&(M$1+$B15-1),dataMail!$H:$H,">"&(M$1+$B15-1)),"-") -> 3 | O15: =IF(DAY(EOMONTH(O$1,0))>=$B15,IFERROR(AVERAGEIFS(dataMail!$P:$P,dataMail!$C:$C,"Confirmation",dataMail!$G:$G,"<="&(O$1+$B15-1),dataMail!$H:$H,">"&(O$1+$B15-1)),"-"),"-") -> 133.84 | P15: =IF(DAY(EOMONTH(O$1,0))>=$B15, 11-COUNTIFS(dataMail!$C:$C,"<>Annulation",dataMail!$G:$G,"<="&(O$1+$B15-1),dataMail!$H:$H,">"&(O$1+$B15-1)),"-") -> 10 | Q15: =IF(DAY(EOMONTH(Q$1,0))>=$B15,IFERROR(AVERAGEIFS(dataMail!$P:$P,dataMail!$C:$C,"Confirmation",dataMail!$G:$G,"<="&(Q$1+$B15-1),dataMail!$H:$H,">"&(Q$1+$B15-1)),"-"),"-") -> 228.706 | R15: =IF(DAY(EOMONTH(Q$1,0))>=$B15, 11-COUNTIFS(dataMail!$C:$C,"<>Annulation",dataMail!$G:$G,"<="&(Q$1+$B15-1),dataMail!$H:$H,">"&(Q$1+$B15-1)),"-") -> -1 | S15: =IF(DAY(EOMONTH(S$1,0))>=$B15,IFERROR(AVERAGEIFS(dataMail!$P:$P,dataMail!$C:$C,"Confirmation",dataMail!$G:$G,"<="&(S$1+$B15-1),dataMail!$H:$H,">"&(S$1+$B15-1)),"-"),"-") -> - | T15: =IF(DAY(EOMONTH(S$1,0))>=$B15, 11-COUNTIFS(dataMail!$C:$C,"<>Annulation",dataMail!$G:$G,"<="&(S$1+$B15-1),dataMail!$H:$H,">"&(S$1+$B15-1)),"-") -> 10 | U15: =IF(DAY(EOMONTH(U$1,0))>=$B15,IFERROR(AVERAGEIFS(dataMail!$P:$P,dataMail!$C:$C,"Confirmation",dataMail!$G:$G,"<="&(U$1+$B15-1),dataMail!$H:$H,">"&(U$1+$B15-1)),"-"),"-") -> 147.096 | V15: =IF(DAY(EOMONTH(U$1,0))>=$B15, 11-COUNTIFS(dataMail!$C:$C,"<>Annulation",dataMail!$G:$G,"<="&(U$1+$B15-1),dataMail!$H:$H,">"&(U$1+$B15-1)),"-") -> 10 | W15: =IF(DAY(EOMONTH(W$1,0))>=$B15,IFERROR(AVERAGEIFS(dataMail!$P:$P,dataMail!$C:$C,"Confirmation",dataMail!$G:$G,"<="&(W$1+$B15-1),dataMail!$H:$H,">"&(W$1+$B15-1)),"-"),"-") -> - | X15: =IF(DAY(EOMONTH(W$1,0))>=$B15, 11-COUNTIFS(dataMail!$C:$C,"<>Annulation",dataMail!$G:$G,"<="&(W$1+$B15-1),dataMail!$H:$H,">"&(W$1+$B15-1)),"-") -> 11 | Y15: =IF(DAY(EOMONTH(Y$1,0))>=$B15,IFERROR(AVERAGEIFS(dataMail!$P:$P,dataMail!$C:$C,"Confirmation",dataMail!$G:$G,"<="&(Y$1+$B15-1),dataMail!$H:$H,">"&(Y$1+$B15-1)),"-"),"-") -> - | Z15: =IF(DAY(EOMONTH(Y$1,0))>=$B15, 11-COUNTIFS(dataMail!$C:$C,"<>Annulation",dataMail!$G:$G,"<="&(Y$1+$B15-1),dataMail!$H:$H,">"&(Y$1+$B15-1)),"-") -> 11 | AA15: =IF(DAY(EOMONTH(AA$1,0))>=$B15,IFERROR(AVERAGEIFS(dataMail!$P:$P,dataMail!$C:$C,"Confirmation",dataMail!$G:$G,"<="&(AA$1+$B15-1),dataMail!$H:$H,">"&(AA$1+$B15-1)),"-"),"-") -> 94.8 | AB15: =IF(DAY(EOMONTH(AA$1,0))>=$B15, 11-COUNTIFS(dataMail!$C:$C,"<>Annulation",dataMail!$G:$G,"<="&(AA$1+$B15-1),dataMail!$H:$H,">"&(AA$1+$B15-1)),"-") -> 9 | AC15: =IF(DAY(EOMONTH(AC$1,0))>=$B15,IFERROR(AVERAGEIFS(dataMail!$P:$P,dataMail!$C:$C,"Confirmation",dataMail!$G:$G,"<="&(AC$1+$B15-1),dataMail!$H:$H,">"&(AC$1+$B15-1)),"-"),"-") -> - | AD15: =IF(DAY(EOMONTH(AC$1,0))>=$B15, 11-COUNTIFS(dataMail!$C:$C,"<>Annulation",dataMail!$G:$G,"<="&(AC$1+$B15-1),dataMail!$H:$H,">"&(AC$1+$B15-1)),"-") -> 11 | AE15: =IF(DAY(EOMONTH(AE$1,0))>=$B15,IFERROR(AVERAGEIFS(dataMail!$P:$P,dataMail!$C:$C,"Confirmation",dataMail!$G:$G,"<="&(AE$1+$B15-1),dataMail!$H:$H,">"&(AE$1+$B15-1)),"-"),"-") -> 94.624 | AF15: =IF(DAY(EOMONTH(AE$1,0))>=$B15, 11-COUNTIFS(dataMail!$C:$C,"<>Annulation",dataMail!$G:$G,"<="&(AE$1+$B15-1),dataMail!$H:$H,">"&(AE$1+$B15-1)),"-") -> 10 | AG15: =IF(DAY(EOMONTH(AG$1,0))>=$B15,IFERROR(AVERAGEIFS(dataMail!$P:$P,dataMail!$C:$C,"Confirmation",dataMail!$G:$G,"<="&(AG$1+$B15-1),dataMail!$H:$H,">"&(AG$1+$B15-1)),"-"),"-") -> - | AH15: =IF(DAY(EOMONTH(AG$1,0))>=$B15, 11-COUNTIFS(dataMail!$C:$C,"<>Annulation",dataMail!$G:$G,"<="&(AG$1+$B15-1),dataMail!$H:$H,">"&(AG$1+$B15-1)),"-") -> 11
B16: 6 | C16: =IF(DAY(EOMONTH(C$1,0))>=$B16,IFERROR(AVERAGEIFS(dataMail!$P:$P,dataMail!$C:$C,"Confirmation",dataMail!$G:$G,"<="&(C$1+$B16-1),dataMail!$H:$H,">"&(C$1+$B16-1)),"-"),"-") -> 125.4208 | D16: =IF(DAY(EOMONTH(C$1,0))>=$B16, 11-COUNTIFS(dataMail!$C:$C,"<>Annulation",dataMail!$G:$G,"<="&(C$1+$B16-1),dataMail!$H:$H,">"&(C$1+$B16-1)),"-") -> 1 | E16: =IF(DAY(EOMONTH(E$1,0))>=$B16,IFERROR(AVERAGEIFS(dataMail!$P:$P,dataMail!$C:$C,"Confirmation",dataMail!$G:$G,"<="&(E$1+$B16-1),dataMail!$H:$H,">"&(E$1+$B16-1)),"-"),"-") -> 152.404 | F16: =IF(DAY(EOMONTH(E$1,0))>=$B16, 11-COUNTIFS(dataMail!$C:$C,"<>Annulation",dataMail!$G:$G,"<="&(E$1+$B16-1),dataMail!$H:$H,">"&(E$1+$B16-1)),"-") -> 3 | G16: =IF(DAY(EOMONTH(G$1,0))>=$B16,IFERROR(AVERAGEIFS(dataMail!$P:$P,dataMail!$C:$C,"Confirmation",dataMail!$G:$G,"<="&(G$1+$B16-1),dataMail!$H:$H,">"&(G$1+$B16-1)),"-"),"-") -> 104.03467 | H16: =IF(DAY(EOMONTH(G$1,0))>=$B16, 11-COUNTIFS(dataMail!$C:$C,"<>Annulation",dataMail!$G:$G,"<="&(G$1+$B16-1),dataMail!$H:$H,">"&(G$1+$B16-1)),"-") -> 2 | I16: =IF(DAY(EOMONTH(I$1,0))>=$B16,IFERROR(AVERAGEIFS(dataMail!$P:$P,dataMail!$C:$C,"Confirmation",dataMail!$G:$G,"<="&(I$1+$B16-1),dataMail!$H:$H,">"&(I$1+$B16-1)),"-"),"-") -> 125.304 | J16: =IF(DAY(EOMONTH(I$1,0))>=$B16, 11-COUNTIFS(dataMail!$C:$C,"<>Annulation",dataMail!$G:$G,"<="&(I$1+$B16-1),dataMail!$H:$H,">"&(I$1+$B16-1)),"-") -> 1 | K16: =IF(DAY(EOMONTH(K$1,0))>=$B16,IFERROR(AVERAGEIFS(dataMail!$P:$P,dataMail!$C:$C,"Confirmation",dataMail!$G:$G,"<="&(K$1+$B16-1),dataMail!$H:$H,">"&(K$1+$B16-1)),"-"),"-") -> 187.4096 | L16: =IF(DAY(EOMONTH(K$1,0))>=$B16, 11-COUNTIFS(dataMail!$C:$C,"<>Annulation",dataMail!$G:$G,"<="&(K$1+$B16-1),dataMail!$H:$H,">"&(K$1+$B16-1)),"-") -> 6 | M16: =IF(DAY(EOMONTH(M$1,0))>=$B16,IFERROR(AVERAGEIFS(dataMail!$P:$P,dataMail!$C:$C,"Confirmation",dataMail!$G:$G,"<="&(M$1+$B16-1),dataMail!$H:$H,">"&(M$1+$B16-1)),"-"),"-") -> 208.27491 | N16: =IF(DAY(EOMONTH(M$1,0))>=$B16, 11-COUNTIFS(dataMail!$C:$C,"<>Annulation",dataMail!$G:$G,"<="&(M$1+$B16-1),dataMail!$H:$H,">"&(M$1+$B16-1)),"-") -> 0 | O16: =IF(DAY(EOMONTH(O$1,0))>=$B16,IFERROR(AVERAGEIFS(dataMail!$P:$P,dataMail!$C:$C,"Confirmation",dataMail!$G:$G,"<="&(O$1+$B16-1),dataMail!$H:$H,">"&(O$1+$B16-1)),"-"),"-") -> - | P16: =IF(DAY(EOMONTH(O$1,0))>=$B16, 11-COUNTIFS(dataMail!$C:$C,"<>Annulation",dataMail!$G:$G,"<="&(O$1+$B16-1),dataMail!$H:$H,">"&(O$1+$B16-1)),"-") -> 11 | Q16: =IF(DAY(EOMONTH(Q$1,0))>=$B16,IFERROR(AVERAGEIFS(dataMail!$P:$P,dataMail!$C:$C,"Confirmation",dataMail!$G:$G,"<="&(Q$1+$B16-1),dataMail!$H:$H,">"&(Q$1+$B16-1)),"-"),"-") -> 234.71709 | R16: =IF(DAY(EOMONTH(Q$1,0))>=$B16, 11-COUNTIFS(dataMail!$C:$C,"<>Annulation",dataMail!$G:$G,"<="&(Q$1+$B16-1),dataMail!$H:$H,">"&(Q$1+$B16-1)),"-") -> 0 | S16: =IF(DAY(EOMONTH(S$1,0))>=$B16,IFERROR(AVERAGEIFS(dataMail!$P:$P,dataMail!$C:$C,"Confirmation",dataMail!$G:$G,"<="&(S$1+$B16-1),dataMail!$H:$H,">"&(S$1+$B16-1)),"-"),"-") -> - | T16: =IF(DAY(EOMONTH(S$1,0))>=$B16, 11-COUNTIFS(dataMail!$C:$C,"<>Annulation",dataMail!$G:$G,"<="&(S$1+$B16-1),dataMail!$H:$H,">"&(S$1+$B16-1)),"-") -> 10 | U16: =IF(DAY(EOMONTH(U$1,0))>=$B16,IFERROR(AVERAGEIFS(dataMail!$P:$P,dataMail!$C:$C,"Confirmation",dataMail!$G:$G,"<="&(U$1+$B16-1),dataMail!$H:$H,">"&(U$1+$B16-1)),"-"),"-") -> 147.096 | V16: =IF(DAY(EOMONTH(U$1,0))>=$B16, 11-COUNTIFS(dataMail!$C:$C,"<>Annulation",dataMail!$G:$G,"<="&(U$1+$B16-1),dataMail!$H:$H,">"&(U$1+$B16-1)),"-") -> 10 | W16: =IF(DAY(EOMONTH(W$1,0))>=$B16,IFERROR(AVERAGEIFS(dataMail!$P:$P,dataMail!$C:$C,"Confirmation",dataMail!$G:$G,"<="&(W$1+$B16-1),dataMail!$H:$H,">"&(W$1+$B16-1)),"-"),"-") -> - | X16: =IF(DAY(EOMONTH(W$1,0))>=$B16, 11-COUNTIFS(dataMail!$C:$C,"<>Annulation",dataMail!$G:$G,"<="&(W$1+$B16-1),dataMail!$H:$H,">"&(W$1+$B16-1)),"-") -> 11 | Y16: =IF(DAY(EOMONTH(Y$1,0))>=$B16,IFERROR(AVERAGEIFS(dataMail!$P:$P,dataMail!$C:$C,"Confirmation",dataMail!$G:$G,"<="&(Y$1+$B16-1),dataMail!$H:$H,">"&(Y$1+$B16-1)),"-"),"-") -> 142.384 | Z16: =IF(DAY(EOMONTH(Y$1,0))>=$B16, 11-COUNTIFS(dataMail!$C:$C,"<>Annulation",dataMail!$G:$G,"<="&(Y$1+$B16-1),dataMail!$H:$H,">"&(Y$1+$B16-1)),"-") -> 9 | AA16: =IF(DAY(EOMONTH(AA$1,0))>=$B16,IFERROR(AVERAGEIFS(dataMail!$P:$P,dataMail!$C:$C,"Confirmation",dataMail!$G:$G,"<="&(AA$1+$B16-1),dataMail!$H:$H,">"&(AA$1+$B16-1)),"-"),"-") -> 94.8 | AB16: =IF(DAY(EOMONTH(AA$1,0))>=$B16, 11-COUNTIFS(dataMail!$C:$C,"<>Annulation",dataMail!$G:$G,"<="&(AA$1+$B16-1),dataMail!$H:$H,">"&(AA$1+$B16-1)),"-") -> 9 | AC16: =IF(DAY(EOMONTH(AC$1,0))>=$B16,IFERROR(AVERAGEIFS(dataMail!$P:$P,dataMail!$C:$C,"Confirmation",dataMail!$G:$G,"<="&(AC$1+$B16-1),dataMail!$H:$H,">"&(AC$1+$B16-1)),"-"),"-") -> - | AD16: =IF(DAY(EOMONTH(AC$1,0))>=$B16, 11-COUNTIFS(dataMail!$C:$C,"<>Annulation",dataMail!$G:$G,"<="&(AC$1+$B16-1),dataMail!$H:$H,">"&(AC$1+$B16-1)),"-") -> 11 | AE16: =IF(DAY(EOMONTH(AE$1,0))>=$B16,IFERROR(AVERAGEIFS(dataMail!$P:$P,dataMail!$C:$C,"Confirmation",dataMail!$G:$G,"<="&(AE$1+$B16-1),dataMail!$H:$H,">"&(AE$1+$B16-1)),"-"),"-") -> 94.624 | AF16: =IF(DAY(EOMONTH(AE$1,0))>=$B16, 11-COUNTIFS(dataMail!$C:$C,"<>Annulation",dataMail!$G:$G,"<="&(AE$1+$B16-1),dataMail!$H:$H,">"&(AE$1+$B16-1)),"-") -> 10 | AG16: =IF(DAY(EOMONTH(AG$1,0))>=$B16,IFERROR(AVERAGEIFS(dataMail!$P:$P,dataMail!$C:$C,"Confirmation",dataMail!$G:$G,"<="&(AG$1+$B16-1),dataMail!$H:$H,">"&(AG$1+$B16-1)),"-"),"-") -> - | AH16: =IF(DAY(EOMONTH(AG$1,0))>=$B16, 11-COUNTIFS(dataMail!$C:$C,"<>Annulation",dataMail!$G:$G,"<="&(AG$1+$B16-1),dataMail!$H:$H,">"&(AG$1+$B16-1)),"-") -> 11
B17: 7 | C17: =IF(DAY(EOMONTH(C$1,0))>=$B17,IFERROR(AVERAGEIFS(dataMail!$P:$P,dataMail!$C:$C,"Confirmation",dataMail!$G:$G,"<="&(C$1+$B17-1),dataMail!$H:$H,">"&(C$1+$B17-1)),"-"),"-") -> 107.83314 | D17: =IF(DAY(EOMONTH(C$1,0))>=$B17, 11-COUNTIFS(dataMail!$C:$C,"<>Annulation",dataMail!$G:$G,"<="&(C$1+$B17-1),dataMail!$H:$H,">"&(C$1+$B17-1)),"-") -> 3 | E17: =IF(DAY(EOMONTH(E$1,0))>=$B17,IFERROR(AVERAGEIFS(dataMail!$P:$P,dataMail!$C:$C,"Confirmation",dataMail!$G:$G,"<="&(E$1+$B17-1),dataMail!$H:$H,">"&(E$1+$B17-1)),"-"),"-") -> 166.69733 | F17: =IF(DAY(EOMONTH(E$1,0))>=$B17, 11-COUNTIFS(dataMail!$C:$C,"<>Annulation",dataMail!$G:$G,"<="&(E$1+$B17-1),dataMail!$H:$H,">"&(E$1+$B17-1)),"-") -> 4 | G17: =IF(DAY(EOMONTH(G$1,0))>=$B17,IFERROR(AVERAGEIFS(dataMail!$P:$P,dataMail!$C:$C,"Confirmation",dataMail!$G:$G,"<="&(G$1+$B17-1),dataMail!$H:$H,">"&(G$1+$B17-1)),"-"),"-") -> 106.959 | H17: =IF(DAY(EOMONTH(G$1,0))>=$B17, 11-COUNTIFS(dataMail!$C:$C,"<>Annulation",dataMail!$G:$G,"<="&(G$1+$B17-1),dataMail!$H:$H,">"&(G$1+$B17-1)),"-") -> 3 | I17: =IF(DAY(EOMONTH(I$1,0))>=$B17,IFERROR(AVERAGEIFS(dataMail!$P:$P,dataMail!$C:$C,"Confirmation",dataMail!$G:$G,"<="&(I$1+$B17-1),dataMail!$H:$H,">"&(I$1+$B17-1)),"-"),"-") -> 118.73257 | J17: =IF(DAY(EOMONTH(I$1,0))>=$B17, 11-COUNTIFS(dataMail!$C:$C,"<>Annulation",dataMail!$G:$G,"<="&(I$1+$B17-1),dataMail!$H:$H,">"&(I$1+$B17-1)),"-") -> 3 | K17: =IF(DAY(EOMONTH(K$1,0))>=$B17,IFERROR(AVERAGEIFS(dataMail!$P:$P,dataMail!$C:$C,"Confirmation",dataMail!$G:$G,"<="&(K$1+$B17-1),dataMail!$H:$H,">"&(K$1+$B17-1)),"-"),"-") -> 168.4352 | L17: =IF(DAY(EOMONTH(K$1,0))>=$B17, 11-COUNTIFS(dataMail!$C:$C,"<>Annulation",dataMail!$G:$G,"<="&(K$1+$B17-1),dataMail!$H:$H,">"&(K$1+$B17-1)),"-") -> 6 | M17: =IF(DAY(EOMONTH(M$1,0))>=$B17,IFERROR(AVERAGEIFS(dataMail!$P:$P,dataMail!$C:$C,"Confirmation",dataMail!$G:$G,"<="&(M$1+$B17-1),dataMail!$H:$H,">"&(M$1+$B17-1)),"-"),"-") -> 131.688 | N17: =IF(DAY(EOMONTH(M$1,0))>=$B17, 11-COUNTIFS(dataMail!$C:$C,"<>Annulation",dataMail!$G:$G,"<="&(M$1+$B17-1),dataMail!$H:$H,">"&(M$1+$B17-1)),"-") -> 6 | O17: =IF(DAY(EOMONTH(O$1,0))>=$B17,IFERROR(AVERAGEIFS(dataMail!$P:$P,dataMail!$C:$C,"Confirmation",dataMail!$G:$G,"<="&(O$1+$B17-1),dataMail!$H:$H,">"&(O$1+$B17-1)),"-"),"-") -> - | P17: =IF(DAY(EOMONTH(O$1,0))>=$B17, 11-COUNTIFS(dataMail!$C:$C,"<>Annulation",dataMail!$G:$G,"<="&(O$1+$B17-1),dataMail!$H:$H,">"&(O$1+$B17-1)),"-") -> 11 | Q17: =IF(DAY(EOMONTH(Q$1,0))>=$B17,IFERROR(AVERAGEIFS(dataMail!$P:$P,dataMail!$C:$C,"Confirmation",dataMail!$G:$G,"<="&(Q$1+$B17-1),dataMail!$H:$H,">"&(Q$1+$B17-1)),"-"),"-") -> 260.21829 | R17: =IF(DAY(EOMONTH(Q$1,0))>=$B17, 11-COUNTIFS(dataMail!$C:$C,"<>Annulation",dataMail!$G:$G,"<="&(Q$1+$B17-1),dataMail!$H:$H,">"&(Q$1+$B17-1)),"-") -> 4 | S17: =IF(DAY(EOMONTH(S$1,0))>=$B17,IFERROR(AVERAGEIFS(dataMail!$P:$P,dataMail!$C:$C,"Confirmation",dataMail!$G:$G,"<="&(S$1+$B17-1),dataMail!$H:$H,">"&(S$1+$B17-1)),"-"),"-") -> - | T17: =IF(DAY(EOMONTH(S$1,0))>=$B17, 11-COUNTIFS(dataMail!$C:$C,"<>Annulation",dataMail!$G:$G,"<="&(S$1+$B17-1),dataMail!$H:$H,">"&(S$1+$B17-1)),"-") -> 11 | U17: =IF(DAY(EOMONTH(U$1,0))>=$B17,IFERROR(AVERAGEIFS(dataMail!$P:$P,dataMail!$C:$C,"Confirmation",dataMail!$G:$G,"<="&(U$1+$B17-1),dataMail!$H:$H,">"&(U$1+$B17-1)),"-"),"-") -> - | V17: =IF(DAY(EOMONTH(U$1,0))>=$B17, 11-COUNTIFS(dataMail!$C:$C,"<>Annulation",dataMail!$G:$G,"<="&(U$1+$B17-1),dataMail!$H:$H,">"&(U$1+$B17-1)),"-") -> 11 | W17: =IF(DAY(EOMONTH(W$1,0))>=$B17,IFERROR(AVERAGEIFS(dataMail!$P:$P,dataMail!$C:$C,"Confirmation",dataMail!$G:$G,"<="&(W$1+$B17-1),dataMail!$H:$H,">"&(W$1+$B17-1)),"-"),"-") -> - | X17: =IF(DAY(EOMONTH(W$1,0))>=$B17, 11-COUNTIFS(dataMail!$C:$C,"<>Annulation",dataMail!$G:$G,"<="&(W$1+$B17-1),dataMail!$H:$H,">"&(W$1+$B17-1)),"-") -> 11 | Y17: =IF(DAY(EOMONTH(Y$1,0))>=$B17,IFERROR(AVERAGEIFS(dataMail!$P:$P,dataMail!$C:$C,"Confirmation",dataMail!$G:$G,"<="&(Y$1+$B17-1),dataMail!$H:$H,">"&(Y$1+$B17-1)),"-"),"-") -> 142.384 | Z17: =IF(DAY(EOMONTH(Y$1,0))>=$B17, 11-COUNTIFS(dataMail!$C:$C,"<>Annulation",dataMail!$G:$G,"<="&(Y$1+$B17-1),dataMail!$H:$H,">"&(Y$1+$B17-1)),"-") -> 9 | AA17: =IF(DAY(EOMONTH(AA$1,0))>=$B17,IFERROR(AVERAGEIFS(dataMail!$P:$P,dataMail!$C:$C,"Confirmation",dataMail!$G:$G,"<="&(AA$1+$B17-1),dataMail!$H:$H,">"&(AA$1+$B17-1)),"-"),"-") -> 92.448 | AB17: =IF(DAY(EOMONTH(AA$1,0))>=$B17, 11-COUNTIFS(dataMail!$C:$C,"<>Annulation",dataMail!$G:$G,"<="&(AA$1+$B17-1),dataMail!$H:$H,">"&(AA$1+$B17-1)),"-") -> 10 | AC17: =IF(DAY(EOMONTH(AC$1,0))>=$B17,IFERROR(AVERAGEIFS(dataMail!$P:$P,dataMail!$C:$C,"Confirmation",dataMail!$G:$G,"<="&(AC$1+$B17-1),dataMail!$H:$H,">"&(AC$1+$B17-1)),"-"),"-") -> - | AD17: =IF(DAY(EOMONTH(AC$1,0))>=$B17, 11-COUNTIFS(dataMail!$C:$C,"<>Annulation",dataMail!$G:$G,"<="&(AC$1+$B17-1),dataMail!$H:$H,">"&(AC$1+$B17-1)),"-") -> 11 | AE17: =IF(DAY(EOMONTH(AE$1,0))>=$B17,IFERROR(AVERAGEIFS(dataMail!$P:$P,dataMail!$C:$C,"Confirmation",dataMail!$G:$G,"<="&(AE$1+$B17-1),dataMail!$H:$H,">"&(AE$1+$B17-1)),"-"),"-") -> 0 | AF17: =IF(DAY(EOMONTH(AE$1,0))>=$B17, 11-COUNTIFS(dataMail!$C:$C,"<>Annulation",dataMail!$G:$G,"<="&(AE$1+$B17-1),dataMail!$H:$H,">"&(AE$1+$B17-1)),"-") -> 10 | AG17: =IF(DAY(EOMONTH(AG$1,0))>=$B17,IFERROR(AVERAGEIFS(dataMail!$P:$P,dataMail!$C:$C,"Confirmation",dataMail!$G:$G,"<="&(AG$1+$B17-1),dataMail!$H:$H,">"&(AG$1+$B17-1)),"-"),"-") -> 128.896 | AH17: =IF(DAY(EOMONTH(AG$1,0))>=$B17, 11-COUNTIFS(dataMail!$C:$C,"<>Annulation",dataMail!$G:$G,"<="&(AG$1+$B17-1),dataMail!$H:$H,">"&(AG$1+$B17-1)),"-") -> 10
B18: 8 | C18: =IF(DAY(EOMONTH(C$1,0))>=$B18,IFERROR(AVERAGEIFS(dataMail!$P:$P,dataMail!$C:$C,"Confirmation",dataMail!$G:$G,"<="&(C$1+$B18-1),dataMail!$H:$H,">"&(C$1+$B18-1)),"-"),"-") -> 139.5328 | D18: =IF(DAY(EOMONTH(C$1,0))>=$B18, 11-COUNTIFS(dataMail!$C:$C,"<>Annulation",dataMail!$G:$G,"<="&(C$1+$B18-1),dataMail!$H:$H,">"&(C$1+$B18-1)),"-") -> 0 | E18: =IF(DAY(EOMONTH(E$1,0))>=$B18,IFERROR(AVERAGEIFS(dataMail!$P:$P,dataMail!$C:$C,"Confirmation",dataMail!$G:$G,"<="&(E$1+$B18-1),dataMail!$H:$H,">"&(E$1+$B18-1)),"-"),"-") -> 188.126 | F18: =IF(DAY(EOMONTH(E$1,0))>=$B18, 11-COUNTIFS(dataMail!$C:$C,"<>Annulation",dataMail!$G:$G,"<="&(E$1+$B18-1),dataMail!$H:$H,">"&(E$1+$B18-1)),"-") -> 6 | G18: =IF(DAY(EOMONTH(G$1,0))>=$B18,IFERROR(AVERAGEIFS(dataMail!$P:$P,dataMail!$C:$C,"Confirmation",dataMail!$G:$G,"<="&(G$1+$B18-1),dataMail!$H:$H,">"&(G$1+$B18-1)),"-"),"-") -> 103.25382 | H18: =IF(DAY(EOMONTH(G$1,0))>=$B18, 11-COUNTIFS(dataMail!$C:$C,"<>Annulation",dataMail!$G:$G,"<="&(G$1+$B18-1),dataMail!$H:$H,">"&(G$1+$B18-1)),"-") -> 0 | I18: =IF(DAY(EOMONTH(I$1,0))>=$B18,IFERROR(AVERAGEIFS(dataMail!$P:$P,dataMail!$C:$C,"Confirmation",dataMail!$G:$G,"<="&(I$1+$B18-1),dataMail!$H:$H,">"&(I$1+$B18-1)),"-"),"-") -> 111.567 | J18: =IF(DAY(EOMONTH(I$1,0))>=$B18, 11-COUNTIFS(dataMail!$C:$C,"<>Annulation",dataMail!$G:$G,"<="&(I$1+$B18-1),dataMail!$H:$H,">"&(I$1+$B18-1)),"-") -> 2 | K18: =IF(DAY(EOMONTH(K$1,0))>=$B18,IFERROR(AVERAGEIFS(dataMail!$P:$P,dataMail!$C:$C,"Confirmation",dataMail!$G:$G,"<="&(K$1+$B18-1),dataMail!$H:$H,">"&(K$1+$B18-1)),"-"),"-") -> 147.1432 | L18: =IF(DAY(EOMONTH(K$1,0))>=$B18, 11-COUNTIFS(dataMail!$C:$C,"<>Annulation",dataMail!$G:$G,"<="&(K$1+$B18-1),dataMail!$H:$H,">"&(K$1+$B18-1)),"-") -> 1 | M18: =IF(DAY(EOMONTH(M$1,0))>=$B18,IFERROR(AVERAGEIFS(dataMail!$P:$P,dataMail!$C:$C,"Confirmation",dataMail!$G:$G,"<="&(M$1+$B18-1),dataMail!$H:$H,">"&(M$1+$B18-1)),"-"),"-") -> 126.59467 | N18: =IF(DAY(EOMONTH(M$1,0))>=$B18, 11-COUNTIFS(dataMail!$C:$C,"<>Annulation",dataMail!$G:$G,"<="&(M$1+$B18-1),dataMail!$H:$H,">"&(M$1+$B18-1)),"-") -> 5 | O18: =IF(DAY(EOMONTH(O$1,0))>=$B18,IFERROR(AVERAGEIFS(dataMail!$P:$P,dataMail!$C:$C,"Confirmation",dataMail!$G:$G,"<="&(O$1+$B18-1),dataMail!$H:$H,">"&(O$1+$B18-1)),"-"),"-") -> 120.576 | P18: =IF(DAY(EOMONTH(O$1,0))>=$B18, 11-COUNTIFS(dataMail!$C:$C,"<>Annulation",dataMail!$G:$G,"<="&(O$1+$B18-1),dataMail!$H:$H,">"&(O$1+$B18-1)),"-") -> 9 | Q18: =IF(DAY(EOMONTH(Q$1,0))>=$B18,IFERROR(AVERAGEIFS(dataMail!$P:$P,dataMail!$C:$C,"Confirmation",dataMail!$G:$G,"<="&(Q$1+$B18-1),dataMail!$H:$H,">"&(Q$1+$B18-1)),"-"),"-") -> 256.74857 | R18: =IF(DAY(EOMONTH(Q$1,0))>=$B18, 11-COUNTIFS(dataMail!$C:$C,"<>Annulation",dataMail!$G:$G,"<="&(Q$1+$B18-1),dataMail!$H:$H,">"&(Q$1+$B18-1)),"-") -> 4 | S18: =IF(DAY(EOMONTH(S$1,0))>=$B18,IFERROR(AVERAGEIFS(dataMail!$P:$P,dataMail!$C:$C,"Confirmation",dataMail!$G:$G,"<="&(S$1+$B18-1),dataMail!$H:$H,">"&(S$1+$B18-1)),"-"),"-") -> 195.96 | T18: =IF(DAY(EOMONTH(S$1,0))>=$B18, 11-COUNTIFS(dataMail!$C:$C,"<>Annulation",dataMail!$G:$G,"<="&(S$1+$B18-1),dataMail!$H:$H,">"&(S$1+$B18-1)),"-") -> 5 | U18: =IF(DAY(EOMONTH(U$1,0))>=$B18,IFERROR(AVERAGEIFS(dataMail!$P:$P,dataMail!$C:$C,"Confirmation",dataMail!$G:$G,"<="&(U$1+$B18-1),dataMail!$H:$H,">"&(U$1+$B18-1)),"-"),"-") -> - | V18: =IF(DAY(EOMONTH(U$1,0))>=$B18, 11-COUNTIFS(dataMail!$C:$C,"<>Annulation",dataMail!$G:$G,"<="&(U$1+$B18-1),dataMail!$H:$H,">"&(U$1+$B18-1)),"-") -> 11 | W18: =IF(DAY(EOMONTH(W$1,0))>=$B18,IFERROR(AVERAGEIFS(dataMail!$P:$P,dataMail!$C:$C,"Confirmation",dataMail!$G:$G,"<="&(W$1+$B18-1),dataMail!$H:$H,">"&(W$1+$B18-1)),"-"),"-") -> - | X18: =IF(DAY(EOMONTH(W$1,0))>=$B18, 11-COUNTIFS(dataMail!$C:$C,"<>Annulation",dataMail!$G:$G,"<="&(W$1+$B18-1),dataMail!$H:$H,">"&(W$1+$B18-1)),"-") -> 11 | Y18: =IF(DAY(EOMONTH(Y$1,0))>=$B18,IFERROR(AVERAGEIFS(dataMail!$P:$P,dataMail!$C:$C,"Confirmation",dataMail!$G:$G,"<="&(Y$1+$B18-1),dataMail!$H:$H,">"&(Y$1+$B18-1)),"-"),"-") -> 142.384 | Z18: =IF(DAY(EOMONTH(Y$1,0))>=$B18, 11-COUNTIFS(dataMail!$C:$C,"<>Annulation",dataMail!$G:$G,"<="&(Y$1+$B18-1),dataMail!$H:$H,">"&(Y$1+$B18-1)),"-") -> 9 | AA18: =IF(DAY(EOMONTH(AA$1,0))>=$B18,IFERROR(AVERAGEIFS(dataMail!$P:$P,dataMail!$C:$C,"Confirmation",dataMail!$G:$G,"<="&(AA$1+$B18-1),dataMail!$H:$H,">"&(AA$1+$B18-1)),"-"),"-") -> - | AB18: =IF(DAY(EOMONTH(AA$1,0))>=$B18, 11-COUNTIFS(dataMail!$C:$C,"<>Annulation",dataMail!$G:$G,"<="&(AA$1+$B18-1),dataMail!$H:$H,">"&(AA$1+$B18-1)),"-") -> 11 | AC18: =IF(DAY(EOMONTH(AC$1,0))>=$B18,IFERROR(AVERAGEIFS(dataMail!$P:$P,dataMail!$C:$C,"Confirmation",dataMail!$G:$G,"<="&(AC$1+$B18-1),dataMail!$H:$H,">"&(AC$1+$B18-1)),"-"),"-") -> - | AD18: =IF(DAY(EOMONTH(AC$1,0))>=$B18, 11-COUNTIFS(dataMail!$C:$C,"<>Annulation",dataMail!$G:$G,"<="&(AC$1+$B18-1),dataMail!$H:$H,">"&(AC$1+$B18-1)),"-") -> 11 | AE18: =IF(DAY(EOMONTH(AE$1,0))>=$B18,IFERROR(AVERAGEIFS(dataMail!$P:$P,dataMail!$C:$C,"Confirmation",dataMail!$G:$G,"<="&(AE$1+$B18-1),dataMail!$H:$H,">"&(AE$1+$B18-1)),"-"),"-") -> 0 | AF18: =IF(DAY(EOMONTH(AE$1,0))>=$B18, 11-COUNTIFS(dataMail!$C:$C,"<>Annulation",dataMail!$G:$G,"<="&(AE$1+$B18-1),dataMail!$H:$H,">"&(AE$1+$B18-1)),"-") -> 10 | AG18: =IF(DAY(EOMONTH(AG$1,0))>=$B18,IFERROR(AVERAGEIFS(dataMail!$P:$P,dataMail!$C:$C,"Confirmation",dataMail!$G:$G,"<="&(AG$1+$B18-1),dataMail!$H:$H,">"&(AG$1+$B18-1)),"-"),"-") -> 128.896 | AH18: =IF(DAY(EOMONTH(AG$1,0))>=$B18, 11-COUNTIFS(dataMail!$C:$C,"<>Annulation",dataMail!$G:$G,"<="&(AG$1+$B18-1),dataMail!$H:$H,">"&(AG$1+$B18-1)),"-") -> 10
